Workbook
Name 在: [1]Template!#REF!

Sheet 2
C2: Employee Attendance Tracker
AR6: Statistical Year： | AS6: 2026
AR8: Statistical Month： | AS8: 2
C10: Attendance Record
E11: =IF(E12="","",COUNTIF(E14:E10001,$AJ$13)) -> 0 | F11: =IF(F12="","",COUNTIF(F14:F10001,$AJ$13)) -> 25 | G11: =IF(G12="","",COUNTIF(G14:G10001,$AJ$13)) -> 21 | H11: =IF(H12="","",COUNTIF(H14:H10001,$AJ$13)) -> 23 | I11: =IF(I12="","",COUNTIF(I14:I10001,$AJ$13)) -> 24 | J11: =IF(J12="","",COUNTIF(J14:J10001,$AJ$13)) -> 23 | K11: =IF(K12="","",COUNTIF(K14:K10001,$AJ$13)) -> 22 | L11: =IF(L12="","",COUNTIF(L14:L10001,$AJ$13)) -> 0 | ... AI11: =IF(AI12="","",COUNTIF(AI14:AI10001,$AJ$13))
C12: No. | D12: Name | E12: =DATE($AS$6,$AS$8,1) -> 46054 | F12: =IFERROR(IF(MONTH(E12+1)<>$AS$8,"",E12+1),"") -> 46055 | G12: =IFERROR(IF(MONTH(F12+1)<>$AS$8,"",F12+1),"") -> 46056 | H12: =IFERROR(IF(MONTH(G12+1)<>$AS$8,"",G12+1),"") -> 46057 | I12: =IFERROR(IF(MONTH(H12+1)<>$AS$8,"",H12+1),"") -> 46058 | J12: =IFERROR(IF(MONTH(I12+1)<>$AS$8,"",I12+1),"") -> 46059 | K12: =IFERROR(IF(MONTH(J12+1)<>$AS$8,"",J12+1),"") -> 46060 | L12: =IFERROR(IF(MONTH(K12+1)<>$AS$8,"",K12+1),"") -> 46061 | M12: =IFERROR(IF(MONTH(L12+1)<>$AS$8,"",L12+1),"") -> 46062 | ... AI12: =IFERROR(IF(MONTH(AH12+1)<>$AS$8,"",AH12+1),"") | AJ12: Totals | AR12: Employee Query | AY12: Menu Custom
AJ13: ='2'!AZ15 -> P | AK13: ='2'!AZ16 -> A | AL13: ='2'!AZ17 -> H | AM13: ='2'!AZ18 -> SL | AN13: ='2'!AZ19 -> CL
C14: C-0001 | D14: Angeeswari | E14: H | F14: A | G14: A | H14: P | I14: P | J14: P | K14: P | L14: H | M14: P | N14: P | O14: P | P14: P | Q14: P | R14: P | S14: H | T14: A | U14: P | V14: P | W14: P | X14: P | Y14: P | Z14: P | AA14: A | AB14: P | AC14: P | AD14: H | AE14: H | AF14: H | AJ14: =COUNTIF(F14:AI14,$AJ$13) -> 18 | AK14: =COUNTIF(F14:AI14,$AK$13) -> 4 | AL14: =COUNTIF(E14:AI14,$AL$13) -> 6 | AM14: =COUNTIF(F14:AI14,$AM$13) -> 0 | AN14: =COUNTIF(F14:AI14,$AN$13) -> 0 | AO14: =IF(AND(D14<>"",AK14=0,AL14=0,AM14=0,AN14=0,AJ14<>0),1,"") | AR14: Employee： | AS14: kaleeswari | AY14: Mean | AZ14: Display | BB14: Query： | BC14: =AS14 -> kaleeswari
C15: C-0002 | D15: Anusuya | E15: H | F15: P | G15: P | H15: P | I15: P | J15: P | K15: P | L15: H | M15: P | N15: P | O15: P | P15: P | Q15: P | R15: P | S15: H | T15: P | U15: P | V15: P | W15: P | X15: P | Y15: P | Z15: P | AA15: P | AB15: P | AC15: P | AD15: H | AE15: H | AF15: H | AJ15: =COUNTIF(F15:AI15,$AJ$13) -> 22 | AK15: =COUNTIF(F15:AI15,$AK$13) -> 0 | AL15: =COUNTIF(E15:AI15,$AL$13) -> 6 | AM15: =COUNTIF(F15:AI15,$AM$13) -> 0 | AN15: =COUNTIF(F15:AI15,$AN$13) -> 0 | AO15: =IF(AND(D15<>"",AK15=0,AL15=0,AM15=0,AN15=0,AJ15<>0),1,"") | AY15: Present | AZ15: P | BB15: No. | BC15: =_xlfn.XLOOKUP($AS$14,$D$14:$D$10001,$C$14:$C$10001,"-") -> C-0010
C16: C-0003 | D16: Barathi | E16: H | F16: P | G16: P | H16: P | I16: P | J16: P | K16: A | L16: H | M16: P | N16: P | O16: P | P16: P | Q16: P | R16: P | S16: H | T16: P | U16: P | V16: P | W16: P | X16: P | Y16: P | Z16: P | AA16: P | AB16: P | AC16: P | AD16: H | AE16: H | AF16: H | AJ16: =COUNTIF(F16:AI16,$AJ$13) -> 21 | AK16: =COUNTIF(F16:AI16,$AK$13) -> 1 | AL16: =COUNTIF(E16:AI16,$AL$13) -> 6 | AM16: =COUNTIF(F16:AI16,$AM$13) -> 0 | AN16: =COUNTIF(F16:AI16,$AN$13) -> 0 | AO16: =IF(AND(D16<>"",AK16=0,AL16=0,AM16=0,AN16=0,AJ16<>0),1,"") | AY16: Absent | AZ16: A | BB16: Attendance Ratio | BC16: =IFERROR(AS20/SUM($AS$20:$AS$24),"-") -> -
C17: C-0004 | D17: Deepa.T | E17: H | F17: P | G17: P | H17: P | I17: P | J17: P | K17: P | L17: H | M17: P | N17: P | O17: P | P17: P | Q17: P | R17: P | S17: H | T17: P | U17: P | V17: P | W17: P | X17: P | Y17: P | Z17: P | AA17: P | AB17: P | AC17: P | AD17: H | AE17: H | AF17: H | AJ17: =COUNTIF(F17:AI17,$AJ$13) -> 22 | AK17: =COUNTIF(F17:AI17,$AK$13) -> 0 | AL17: =COUNTIF(E17:AI17,$AL$13) -> 6 | AM17: =COUNTIF(F17:AI17,$AM$13) -> 0 | AN17: =COUNTIF(F17:AI17,$AN$13) -> 0 | AO17: =IF(AND(D17<>"",AK17=0,AL17=0,AM17=0,AN17=0,AJ17<>0),1,"") | AY17: Holiday | AZ17: H
C18: C-0005 | D18: Dharini | E18: H | F18: P | G18: P | H18: P | I18: P | J18: A | K18: P | L18: H | M18: P | N18: P | O18: A | P18: P | Q18: P | R18: P | S18: H | T18: P | U18: P | V18: P | W18: A | X18: P | Y18: P | Z18: P | AA18: P | AB18: P | AC18: P | AD18: H | AE18: H | AF18: H | AJ18: =COUNTIF(F18:AI18,$AJ$13) -> 19 | AK18: =COUNTIF(F18:AI18,$AK$13) -> 3 | AL18: =COUNTIF(E18:AI18,$AL$13) -> 6 | AM18: =COUNTIF(F18:AI18,$AM$13) -> 0 | AN18: =COUNTIF(F18:AI18,$AN$13) -> 0 | AO18: =IF(AND(D18<>"",AK18=0,AL18=0,AM18=0,AN18=0,AJ18<>0),1,"") | AY18: Sick Leave | AZ18: SL
C19: C-0006 | D19: Gayathri | E19: H | F19: P | G19: P | H19: P | I19: P | J19: A | K19: P | L19: H | M19: P | N19: P | O19: P | P19: P | Q19: P | R19: P | S19: H | T19: P | U19: P | V19: P | W19: P | X19: P | Y19: P | Z19: P | AA19: A | AB19: P | AC19: P | AD19: H | AE19: H | AF19: H | AJ19: =COUNTIF(F19:AI19,$AJ$13) -> 20 | AK19: =COUNTIF(F19:AI19,$AK$13) -> 2 | AL19: =COUNTIF(E19:AI19,$AL$13) -> 6 | AM19: =COUNTIF(F19:AI19,$AM$13) -> 0 | AN19: =COUNTIF(F19:AI19,$AN$13) -> 0 | AO19: =IF(AND(D19<>"",AK19=0,AL19=0,AM19=0,AN19=0,AJ19<>0),1,"") | AY19: Casual | AZ19: CL | BB19: Present Total | BC19: =SUM(AJ14:AJ1001) -> 511
C20: C-0007 | D20: Hema | E20: H | F20: P | G20: P | H20: P | I20: P | J20: P | K20: P | L20: H | M20: P | N20: P | O20: P | P20: P | Q20: P | R20: P | S20: H | T20: P | U20: P | V20: P | W20: P | X20: P | Y20: P | Z20: P | AA20: P | AB20: P | AC20: P | AD20: H | AE20: H | AF20: H | AJ20: =COUNTIF(F20:AI20,$AJ$13) -> 22 | AK20: =COUNTIF(F20:AI20,$AK$13) -> 0 | AL20: =COUNTIF(E20:AI20,$AL$13) -> 6 | AM20: =COUNTIF(F20:AI20,$AM$13) -> 0 | AN20: =COUNTIF(F20:AI20,$AN$13) -> 0 | AO20: =IF(AND(D20<>"",AK20=0,AL20=0,AM20=0,AN20=0,AJ20<>0),1,"") | AR20: =AY15&" :" -> Present : | AS20: =_xlfn.XLOOKUP($AS$14,$D$14:$D$10001,$AJ$14:$AJ$10001,"-") -> #NAME? | BB20: Difference | BC20: =SUM(AK14:AN1001) -> 273
C21: C-0008 | D21: Jeevitha | E21: H | F21: P | G21: P | H21: P | I21: P | J21: P | K21: P | L21: H | M21: P | N21: A | O21: P | P21: P | Q21: A | R21: P | S21: H | T21: P | U21: P | V21: P | W21: P | X21: P | Y21: P | Z21: P | AA21: P | AB21: P | AC21: P | AD21: H | AE21: H | AF21: H | AJ21: =COUNTIF(F21:AI21,$AJ$13) -> 20 | AK21: =COUNTIF(F21:AI21,$AK$13) -> 2 | AL21: =COUNTIF(E21:AI21,$AL$13) -> 6 | AM21: =COUNTIF(F21:AI21,$AM$13) -> 0 | AN21: =COUNTIF(F21:AI21,$AN$13) -> 0 | AO21: =IF(AND(D21<>"",AK21=0,AL21=0,AM21=0,AN21=0,AJ21<>0),1,"") | AR21: =AY16&" :" -> Absent : | AS21: =_xlfn.XLOOKUP($AS$14,$D$14:$D$10001,$AK$14:$AK$10001,"-") -> #NAME? | BB21: Ratio | BC21: =IFERROR(BC19/SUM(BC19:BC20),"-") -> 0.65178571
C22: C-0009 | D22: Jeynandhini | E22: H | F22: P | G22: P | H22: P | I22: P | J22: P | K22: P | L22: H | M22: P | N22: P | O22: P | P22: P | Q22: P | R22: P | S22: H | T22: P | U22: P | V22: P | W22: P | X22: P | Y22: P | Z22: P | AA22: P | AB22: P | AC22: P | AD22: H | AE22: H | AF22: H | AJ22: =COUNTIF(F22:AI22,$AJ$13) -> 22 | AK22: =COUNTIF(F22:AI22,$AK$13) -> 0 | AL22: =COUNTIF(E22:AI22,$AL$13) -> 6 | AM22: =COUNTIF(F22:AI22,$AM$13) -> 0 | AN22: =COUNTIF(F22:AI22,$AN$13) -> 0 | AO22: =IF(AND(D22<>"",AK22=0,AL22=0,AM22=0,AN22=0,AJ22<>0),1,"") | AR22: =AY17&" :" -> Holiday : | AS22: =_xlfn.XLOOKUP($AS$14,$D$14:$D$10001,$AL$14:$AL$10001,"-") -> #NAME? | BB22: Full attendance | BC22: =COUNTIF(AO14:AO10001,1)&" People" -> 0 People
C23: C-0010 | D23: kaleeswari | E23: H | F23: P | G23: P | H23: P | I23: P | J23: P | K23: P | L23: H | M23: P | N23: P | O23: P | P23: P | Q23: P | R23: P | S23: H | T23: P | U23: P | V23: P | W23: P | X23: P | Y23: P | Z23: P | AA23: P | AB23: P | AC23: P | AD23: H | AE23: H | AF23: H | AJ23: =COUNTIF(F23:AI23,$AJ$13) -> 22 | AK23: =COUNTIF(F23:AI23,$AK$13) -> 0 | AL23: =COUNTIF(E23:AI23,$AL$13) -> 6 | AM23: =COUNTIF(F23:AI23,$AM$13) -> 0 | AN23: =COUNTIF(F23:AI23,$AN$13) -> 0 | AO23: =IF(AND(D23<>"",AK23=0,AL23=0,AM23=0,AN23=0,AJ23<>0),1,"") | AR23: =AY18&" :" -> Sick Leave : | AS23: =_xlfn.XLOOKUP($AS$14,$D$14:$D$10001,$AM$14:$AM$10001,"-") -> #NAME? | BB23: Number of employees | BC23: =COUNTA(D14:D10001)&" People" -> 28 People
C24: C-0011 | D24: Karthika | E24: H | F24: P | G24: P | H24: P | I24: P | J24: P | K24: P | L24: H | M24: P | N24: P | O24: P | P24: P | Q24: P | R24: P | S24: H | T24: P | U24: P | V24: P | W24: P | X24: A | Y24: P | Z24: P | AA24: P | AB24: P | AC24: P | AD24: H | AE24: H | AF24: H | AJ24: =COUNTIF(F24:AI24,$AJ$13) -> 21 | AK24: =COUNTIF(F24:AI24,$AK$13) -> 1 | AL24: =COUNTIF(E24:AI24,$AL$13) -> 6 | AM24: =COUNTIF(F24:AI24,$AM$13) -> 0 | AN24: =COUNTIF(F24:AI24,$AN$13) -> 0 | AO24: =IF(AND(D24<>"",AK24=0,AL24=0,AM24=0,AN24=0,AJ24<>0),1,"") | AR24: =AY19&" :" -> Casual : | AS24: =_xlfn.XLOOKUP($AS$14,$D$14:$D$10001,$AN$14:$AN$10001,"-") -> #NAME?
C25: C-0012 | D25: Kasthuri | E25: H | F25: P | G25: P | H25: P | I25: P | J25: P | K25: P | L25: H | M25: P | N25: P | O25: P | P25: P | Q25: P | R25: P | S25: H | T25: P | U25: A | V25: P | W25: P | X25: P | Y25: P | Z25: P | AA25: P | AB25: P | AC25: P | AD25: H | AE25: H | AF25: H | AJ25: =COUNTIF(F25:AI25,$AJ$13) -> 21 | AK25: =COUNTIF(F25:AI25,$AK$13) -> 1 | AL25: =COUNTIF(E25:AI25,$AL$13) -> 6 | AM25: =COUNTIF(F25:AI25,$AM$13) -> 0 | AN25: =COUNTIF(F25:AI25,$AN$13) -> 0 | AO25: =IF(AND(D25<>"",AK25=0,AL25=0,AM25=0,AN25=0,AJ25<>0),1,"")
C26: C-0013 | D26: Kulanthayammal | E26: H | F26: P | G26: A | H26: P | I26: P | J26: P | K26: P | L26: H | M26: P | N26: P | O26: P | P26: P | Q26: P | R26: P | S26: H | T26: A | U26: A | V26: A | W26: A | X26: A | Y26: A | Z26: A | AA26: A | AB26: A | AC26: A | AD26: H | AE26: H | AF26: H | AJ26: =COUNTIF(F26:AI26,$AJ$13) -> 11 | AK26: =COUNTIF(F26:AI26,$AK$13) -> 11 | AL26: =COUNTIF(E26:AI26,$AL$13) -> 6 | AM26: =COUNTIF(F26:AI26,$AM$13) -> 0 | AN26: =COUNTIF(F26:AI26,$AN$13) -> 0 | AO26: =IF(AND(D26<>"",AK26=0,AL26=0,AM26=0,AN26=0,AJ26<>0),1,"")
C27: C-0014 | D27: Lakshmipriya | E27: H | F27: P | G27: P | H27: P | I27: P | J27: P | K27: P | L27: H | M27: P | N27: P | O27: P | P27: P | Q27: P | R27: P | S27: H | T27: P | U27: P | V27: P | W27: A | X27: P | Y27: P | Z27: P | AA27: P | AB27: A | AC27: A | AD27: H | AE27: H | AF27: H | AJ27: =COUNTIF(F27:AI27,$AJ$13) -> 19 | AK27: =COUNTIF(F27:AI27,$AK$13) -> 3 | AL27: =COUNTIF(E27:AI27,$AL$13) -> 6 | AM27: =COUNTIF(F27:AI27,$AM$13) -> 0 | AN27: =COUNTIF(F27:AI27,$AN$13) -> 0 | AO27: =IF(AND(D27<>"",AK27=0,AL27=0,AM27=0,AN27=0,AJ27<>0),1,"")
C28: C-0015 | D28: Mathavi | E28: H | F28: P | G28: A | H28: P | I28: P | J28: P | K28: P | L28: H | M28: P | N28: P | O28: P | P28: P | Q28: P | R28: P | S28: H | T28: P | U28: A | V28: P | W28: P | X28: P | Y28: P | Z28: P | AA28: P | AB28: P | AC28: P | AD28: H | AE28: H | AF28: H | AJ28: =COUNTIF(F28:AI28,$AJ$13) -> 20 | AK28: =COUNTIF(F28:AI28,$AK$13) -> 2 | AL28: =COUNTIF(E28:AI28,$AL$13) -> 6 | AM28: =COUNTIF(F28:AI28,$AM$13) -> 0 | AN28: =COUNTIF(F28:AI28,$AN$13) -> 0 | AO28: =IF(AND(D28<>"",AK28=0,AL28=0,AM28=0,AN28=0,AJ28<>0),1,"")
C29: C-0016 | D29: Meena | E29: H | F29: P | G29: P | H29: P | I29: P | J29: P | K29: P | L29: H | M29: P | N29: P | O29: P | P29: P | Q29: P | R29: P | S29: H | T29: P | U29: P | V29: A | W29: P | X29: P | Y29: P | Z29: P | AA29: P | AB29: P | AC29: P | AD29: H | AE29: H | AF29: H | AJ29: =COUNTIF(F29:AI29,$AJ$13) -> 21 | AK29: =COUNTIF(F29:AI29,$AK$13) -> 1 | AL29: =COUNTIF(E29:AI29,$AL$13) -> 6 | AM29: =COUNTIF(F29:AI29,$AM$13) -> 0 | AN29: =COUNTIF(F29:AI29,$AN$13) -> 0 | AO29: =IF(AND(D29<>"",AK29=0,AL29=0,AM29=0,AN29=0,AJ29<>0),1,"")
C30: C-0017 | D30: Nithiya | E30: H | F30: P | G30: P | H30: P | I30: P | J30: P | K30: P | L30: H | M30: P | N30: P | O30: P | P30: P | Q30: P | R30: A | S30: H | T30: P | U30: P | V30: P | W30: P | X30: A | Y30: P | Z30: P | AA30: P | AB30: P | AC30: P | AD30: H | AE30: H | AF30: H | AJ30: =COUNTIF(F30:AI30,$AJ$13) -> 20 | AK30: =COUNTIF(F30:AI30,$AK$13) -> 2 | AL30: =COUNTIF(E30:AI30,$AL$13) -> 6 | AM30: =COUNTIF(F30:AI30,$AM$13) -> 0 | AN30: =COUNTIF(F30:AI30,$AN$13) -> 0 | AO30: =IF(AND(D30<>"",AK30=0,AL30=0,AM30=0,AN30=0,AJ30<>0),1,"")
C31: C-0018 | D31: Pandiselvi | E31: H | F31: P | G31: P | H31: P | I31: P | J31: P | K31: P | L31: H | M31: P | N31: A | O31: P | P31: P | Q31: P | R31: A | S31: H | T31: A | U31: P | V31: P | W31: P | X31: P | Y31: P | Z31: P | AA31: P | AB31: A | AC31: P | AD31: H | AE31: H | AF31: H | AJ31: =COUNTIF(F31:AI31,$AJ$13) -> 18 | AK31: =COUNTIF(F31:AI31,$AK$13) -> 4 | AL31: =COUNTIF(E31:AI31,$AL$13) -> 6 | AM31: =COUNTIF(F31:AI31,$AM$13) -> 0 | AN31: =COUNTIF(F31:AI31,$AN$13) -> 0 | AO31: =IF(AND(D31<>"",AK31=0,AL31=0,AM31=0,AN31=0,AJ31<>0),1,"")
C32: C-0019 | D32: Ponnarasi | E32: H | F32: P | G32: A | H32: P | I32: P | J32: P | K32: P | L32: H | M32: P | N32: P | O32: P | P32: P | Q32: P | R32: P | S32: H | T32: A | U32: A | V32: A | W32: A | X32: A | Y32: A | Z32: A | AA32: A | AB32: A | AC32: A | AD32: H | AE32: H | AF32: H | AJ32: =COUNTIF(F32:AI32,$AJ$13) -> 11 | AK32: =COUNTIF(F32:AI32,$AK$13) -> 11 | AL32: =COUNTIF(E32:AI32,$AL$13) -> 6 | AM32: =COUNTIF(F32:AI32,$AM$13) -> 0 | AN32: =COUNTIF(F32:AI32,$AN$13) -> 0 | AO32: =IF(AND(D32<>"",AK32=0,AL32=0,AM32=0,AN32=0,AJ32<>0),1,"")
C33: C-0020 | D33: Priyadharshini.k | E33: H | F33: P | G33: P | H33: P | I33: P | J33: P | K33: P | L33: H | M33: P | N33: P | O33: P | P33: P | Q33: P | R33: P | S33: H | T33: P | U33: P | V33: P | W33: P | X33: P | Y33: P | Z33: P | AA33: P | AB33: P | AC33: P | AD33: H | AE33: H | AF33: H | AJ33: =COUNTIF(F33:AI33,$AJ$13) -> 22 | AK33: =COUNTIF(F33:AI33,$AK$13) -> 0 | AL33: =COUNTIF(E33:AI33,$AL$13) -> 6 | AM33: =COUNTIF(F33:AI33,$AM$13) -> 0 | AN33: =COUNTIF(F33:AI33,$AN$13) -> 0 | AO33: =IF(AND(D33<>"",AK33=0,AL33=0,AM33=0,AN33=0,AJ33<>0),1,"")
C34: C-0021 | D34: Reshma | E34: H | F34: P | G34: P | H34: A | I34: P | J34: P | K34: P | L34: H | M34: P | N34: P | O34: P | P34: P | Q34: P | R34: P | S34: H | T34: P | U34: P | V34: P | W34: P | X34: P | Y34: P | Z34: P | AA34: P | AB34: P | AC34: P | AD34: H | AE34: H | AF34: H | AJ34: =COUNTIF(F34:AI34,$AJ$13) -> 21 | AK34: =COUNTIF(F34:AI34,$AK$13) -> 1 | AL34: =COUNTIF(E34:AI34,$AL$13) -> 6 | AM34: =COUNTIF(F34:AI34,$AM$13) -> 0 | AN34: =COUNTIF(F34:AI34,$AN$13) -> 0 | AO34: =IF(AND(D34<>"",AK34=0,AL34=0,AM34=0,AN34=0,AJ34<>0),1,"")
C35: C-0022 | D35: Selvapriya | E35: H | F35: P | G35: A | H35: P | I35: P | J35: P | K35: A | L35: H | M35: P | N35: A | O35: A | P35: A | Q35: A | R35: P | S35: H | T35: P | U35: P | V35: P | W35: A | X35: A | Y35: A | Z35: A | AA35: A | AB35: A | AC35: A | AD35: H | AE35: H | AF35: H | AJ35: =COUNTIF(F35:AI35,$AJ$13) -> 9 | AK35: =COUNTIF(F35:AI35,$AK$13) -> 13 | AL35: =COUNTIF(E35:AI35,$AL$13) -> 6 | AM35: =COUNTIF(F35:AI35,$AM$13) -> 0 | AN35: =COUNTIF(F35:AI35,$AN$13) -> 0 | AO35: =IF(AND(D35<>"",AK35=0,AL35=0,AM35=0,AN35=0,AJ35<>0),1,"")
C36: C-0023 | D36: Sheeja | E36: H | F36: P | G36: P | H36: A | I36: A | J36: P | K36: A | L36: H | M36: A | N36: A | O36: A | P36: A | Q36: A | R36: A | S36: H | T36: A | U36: A | V36: A | W36: A | X36: A | Y36: A | Z36: A | AA36: A | AB36: A | AC36: A | AD36: H | AE36: H | AF36: H | AJ36: =COUNTIF(F36:AI36,$AJ$13) -> 3 | AK36: =COUNTIF(F36:AI36,$AK$13) -> 19 | AL36: =COUNTIF(E36:AI36,$AL$13) -> 6 | AM36: =COUNTIF(F36:AI36,$AM$13) -> 0 | AN36: =COUNTIF(F36:AI36,$AN$13) -> 0 | AO36: =IF(AND(D36<>"",AK36=0,AL36=0,AM36=0,AN36=0,AJ36<>0),1,"")
... C38: C-0025 | D38: swathi | E38: H | F38: P | G38: P | H38: P | I38: P | J38: P | K38: P | L38: H | M38: P | N38: P | O38: P | P38: P | Q38: P | R38: P | S38: H | T38: P | U38: P | V38: P | W38: P | X38: P | Y38: A | Z38: A | AA38: P | AB38: P | AC38: P | AD38: H | AE38: H | AF38: H | AJ38: =COUNTIF(F38:AI38,$AJ$13) -> 20 | AK38: =COUNTIF(F38:AI38,$AK$13) -> 2 | AL38: =COUNTIF(E38:AI38,$AL$13) -> 6 | AM38: =COUNTIF(F38:AI38,$AM$13) -> 0 | AN38: =COUNTIF(F38:AI38,$AN$13) -> 0 | AO38: =IF(AND(D38<>"",AK38=0,AL38=0,AM38=0,AN38=0,AJ38<>0),1,"")
C39: C-0026 | D39: Varshini | E39: H | F39: P | G39: P | H39: P | I39: P | J39: P | K39: P | L39: H | M39: P | N39: P | O39: P | P39: P | Q39: P | R39: P | S39: H | T39: P | U39: P | V39: P | W39: P | X39: P | Y39: P | Z39: P | AA39: P | AB39: P | AC39: P | AD39: H | AE39: H | AF39: H | AJ39: =COUNTIF(F39:AI39,$AJ$13) -> 22 | AK39: =COUNTIF(F39:AI39,$AK$13) -> 0 | AL39: =COUNTIF(E39:AI39,$AL$13) -> 6 | AM39: =COUNTIF(F39:AI39,$AM$13) -> 0 | AN39: =COUNTIF(F39:AI39,$AN$13) -> 0 | AO39: =IF(AND(D39<>"",AK39=0,AL39=0,AM41=0,AN39=0,AJ39<>0),1,"")
C40: C-0027 | D40: Deepa.M | E40: H | F40: A | G40: A | H40: A | I40: A | J40: A | K40: A | L40: H | M40: P | N40: P | O40: P | P40: P | Q40: P | R40: P | S40: H | T40: P | U40: P | V40: P | W40: P | X40: P | Y40: P | Z40: A | AA40: A | AB40: P | AC40: P | AD40: H | AE40: H | AF40: H | AJ40: =COUNTIF(F40:AI40,$AJ$13) -> 14 | AK40: =COUNTIF(F40:AI40,$AK$13) -> 8 | AL40: =COUNTIF(E40:AI40,$AL$13) -> 6 | AM40: =COUNTIF(F40:AI40,$AM$13) -> 0 | AN40: =COUNTIF(F40:AI40,$AN$13) -> 0 | AO40: =IF(AND(D40<>"",AK40=0,AL40=0,AM42=0,AN40=0,AJ40<>0),1,"")
C41: C-0028 | D41: Priyadharshini.T | E41: H | F41: H | G41: H | H41: H | I41: H | J41: H | K41: H | L41: H | M41: H | N41: p | O41: p | P41: A | Q41: P | R41: P | S41: H | T41: P | U41: P | V41: P | W41: P | X41: P | Y41: P | Z41: P | AA41: P | AB41: P | AC41: P | AD41: H | AE41: H | AF41: H | AJ41: =COUNTIF(F41:AI41,$AJ$13) -> 14 | AK41: =COUNTIF(F41:AI41,$AK$13) -> 1 | AL41: =COUNTIF(E41:AI41,$AL$13) -> 13 | AM41: =COUNTIF(F41:AI41,$AM$13) -> 0 | AN41: =COUNTIF(F41:AI41,$AN$13) -> 0 | AO41: =IF(AND(D41<>"",AK41=0,AL41=0,AM43=0,AN41=0,AJ41<>0),1,"")
AO42: =IF(AND(D42<>"",AK42=0,AL42=0,AM42=0,AN42=0,AJ42<>0),1,"")
AO43: =IF(AND(D43<>"",AK43=0,AL43=0,AM43=0,AN43=0,AJ43<>0),1,"")
AO44: =IF(AND(D44<>"",AK44=0,AL44=0,AM44=0,AN44=0,AJ44<>0),1,"")
AO45: =IF(AND(D45<>"",AK45=0,AL45=0,AM45=0,AN45=0,AJ45<>0),1,"")
AO46: =IF(AND(D46<>"",AK46=0,AL46=0,AM46=0,AN46=0,AJ46<>0),1,"")
AO47: =IF(AND(D47<>"",AK47=0,AL47=0,AM47=0,AN47=0,AJ47<>0),1,"")
...

Sheet 3
C2: Employee Attendance Tracker
AR6: Statistical Year： | AS6: ='2'!AS6 -> 2026
AR8: Statistical Month： | AS8: 3
C10: Attendance Record
E11: =IF(E12="","",COUNTIF(E14:E10001,$AJ$13)) -> 0 | F11: =IF(F12="","",COUNTIF(F14:F10001,$AJ$13)) -> 2 | G11: =IF(G12="","",COUNTIF(G14:G10001,$AJ$13)) -> 2 | H11: =IF(H12="","",COUNTIF(H14:H10001,$AJ$13)) -> 2 | I11: =IF(I12="","",COUNTIF(I14:I10001,$AJ$13)) -> 2 | J11: =IF(J12="","",COUNTIF(J14:J10001,$AJ$13)) -> 2 | K11: =IF(K12="","",COUNTIF(K14:K10001,$AJ$13)) -> 2 | L11: =IF(L12="","",COUNTIF(L14:L10001,$AJ$13)) -> 0 | ... AI11: =IF(AI12="","",COUNTIF(AI14:AI10001,$AJ$13)) -> 11
C12: No. | D12: Name | E12: =DATE($AS$6,$AS$8,1) -> 46082 | F12: =IFERROR(IF(MONTH(E12+1)<>$AS$8,"",E12+1),"") -> 46083 | G12: =IFERROR(IF(MONTH(F12+1)<>$AS$8,"",F12+1),"") -> 46084 | H12: =IFERROR(IF(MONTH(G12+1)<>$AS$8,"",G12+1),"") -> 46085 | I12: =IFERROR(IF(MONTH(H12+1)<>$AS$8,"",H12+1),"") -> 46086 | J12: =IFERROR(IF(MONTH(I12+1)<>$AS$8,"",I12+1),"") -> 46087 | K12: =IFERROR(IF(MONTH(J12+1)<>$AS$8,"",J12+1),"") -> 46088 | L12: =IFERROR(IF(MONTH(K12+1)<>$AS$8,"",K12+1),"") -> 46089 | M12: =IFERROR(IF(MONTH(L12+1)<>$AS$8,"",L12+1),"") -> 46090 | ... AI12: =IFERROR(IF(MONTH(AH12+1)<>$AS$8,"",AH12+1),"") -> 46112 | AJ12: Totals | AR12: Employee Query | AY12: Menu Custom
AJ13: ='3'!AZ15 -> P | AK13: ='3'!AZ16 -> A | AL13: ='3'!AZ17 -> H | AM13: ='3'!AZ18 -> SL | AN13: ='3'!AZ19 -> CL
C14: 1 | D14: Jeyanandhini | F14: P | G14: P | H14: P | I14: P | J14: P | K14: P | L14: A | M14: P | N14: P | O14: P | P14: P | Q14: P | R14: P | S14: A | T14: P | U14: P | V14: P | W14: P | X14: P | Y14: P | Z14: H | AA14: P | AB14: P | AC14: P | AD14: P | AE14: P | AF14: P | AG14: H | AH14: P | AI14: P | AJ14: =COUNTIF(E14:AI14,$AJ$13) -> 26 | AK14: =COUNTIF(E14:AI14,$AK$13) -> 2 | AL14: =COUNTIF(E14:AI14,$AL$13) -> 2 | AM14: =COUNTIF(E14:AI14,$AM$13) -> 0 | AN14: =COUNTIF(E14:AI14,$AN$13) -> 0 | AO14: =IF(AND(D14<>"",AK14=0,AL14=0,AM14=0,AN14=0,AJ14<>0),1,"") | AR14: Employee： | AS14: Deepa.T | AY14: Mean | AZ14: Display | BB14: Query： | BC14: =AS14 -> Deepa.T
C15: 2 | D15: Anusuya | F15: P | G15: P | H15: P | I15: P | J15: P | K15: P | L15: A | M15: P | N15: P | O15: P | P15: P | Q15: P | R15: P | S15: A | T15: P | U15: P | V15: P | W15: P | X15: P | Y15: P | Z15: H | AA15: A | AB15: P | AC15: P | AD15: P | AE15: P | AF15: P | AG15: H | AH15: P | AI15: P | AJ15: =COUNTIF(E15:AI15,$AJ$13) -> 25 | AK15: =COUNTIF(E15:AI15,$AK$13) -> 3 | AL15: =COUNTIF(E15:AI15,$AL$13) -> 2 | AM15: =COUNTIF(E15:AI15,$AM$13) -> 0 | AN15: =COUNTIF(E15:AI15,$AN$13) -> 0 | AO15: =IF(AND(D15<>"",AK15=0,AL15=0,AM15=0,AN15=0,AJ15<>0),1,"") | AY15: Present | AZ15: P | BB15: No. | BC15: =_xlfn.XLOOKUP($AS$14,$D$14:$D$10001,$C$14:$C$10001,"-") -> 12
C16: 3 | D16: Lakshmipriya | X16: A | Y16: P | Z16: H | AA16: P | AB16: P | AC16: A | AD16: P | AE16: P | AF16: P | AG16: H | AH16: P | AI16: A | AJ16: =COUNTIF(E16:AI16,$AJ$13) -> 7 | AK16: =COUNTIF(E16:AI16,$AK$13) -> 3 | AL16: =COUNTIF(E16:AI16,$AL$13) -> 2 | AM16: =COUNTIF(E16:AI16,$AM$13) -> 0 | AN16: =COUNTIF(E16:AI16,$AN$13) -> 0 | AO16: =IF(AND(D16<>"",AK16=0,AL16=0,AM16=0,AN16=0,AJ16<>0),1,"") | AY16: Absent | AZ16: A | BB16: Attendance Ratio | BC16: =IFERROR(AS20/SUM($AS$20:$AS$24),"-") -> 0.66666667
C17: 4 | D17: Varshini | X17: P | Y17: P | Z17: H | AA17: P | AB17: A | AC17: P | AD17: P | AE17: P | AF17: P | AG17: H | AH17: P | AI17: P | AJ17: =COUNTIF(E17:AI17,$AJ$13) -> 9 | AK17: =COUNTIF(E17:AI17,$AK$13) -> 1 | AL17: =COUNTIF(E17:AI17,$AL$13) -> 2 | AM17: =COUNTIF(E17:AI17,$AM$13) -> 0 | AN17: =COUNTIF(E17:AI17,$AN$13) -> 0 | AO17: =IF(AND(D17<>"",AK17=0,AL17=0,AM17=0,AN17=0,AJ17<>0),1,"") | AY17: Holiday | AZ17: H
C18: 5 | D18: Kaleeswari | X18: P | Y18: P | Z18: H | AA18: P | AB18: P | AC18: P | AD18: P | AE18: P | AF18: P | AG18: H | AH18: A | AI18: A | AJ18: =COUNTIF(E18:AI18,$AJ$13) -> 8 | AK18: =COUNTIF(E18:AI18,$AK$13) -> 2 | AL18: =COUNTIF(E18:AI18,$AL$13) -> 2 | AM18: =COUNTIF(E18:AI18,$AM$13) -> 0 | AN18: =COUNTIF(E18:AI18,$AN$13) -> 0 | AO18: =IF(AND(D18<>"",AK18=0,AL18=0,AM18=0,AN18=0,AJ18<>0),1,"") | AY18: Sick Leave | AZ18: SL
C19: 6 | D19: Priyadharshini | X19: A | Y19: P | Z19: H | AA19: P | AB19: P | AC19: P | AD19: P | AE19: P | AF19: P | AG19: H | AH19: A | AI19: A | AJ19: =COUNTIF(E19:AI19,$AJ$13) -> 7 | AK19: =COUNTIF(E19:AI19,$AK$13) -> 3 | AL19: =COUNTIF(E19:AI19,$AL$13) -> 2 | AM19: =COUNTIF(E19:AI19,$AM$13) -> 0 | AN19: =COUNTIF(E19:AI19,$AN$13) -> 0 | AO19: =IF(AND(D19<>"",AK19=0,AL19=0,AM19=0,AN19=0,AJ19<>0),1,"") | AY19: Casual | AZ19: CL | BB19: Present Total | BC19: =SUM(AJ14:AJ1001) -> 154
C20: 7 | D20: Gayathri | X20: P | Y20: P | Z20: H | AA20: P | AB20: P | AC20: P | AD20: P | AE20: A | AF20: P | AG20: H | AH20: P | AI20: P | AJ20: =COUNTIF(E20:AI20,$AJ$13) -> 9 | AK20: =COUNTIF(E20:AI20,$AK$13) -> 1 | AL20: =COUNTIF(E20:AI20,$AL$13) -> 2 | AM20: =COUNTIF(E20:AI20,$AM$13) -> 0 | AN20: =COUNTIF(E20:AI20,$AN$13) -> 0 | AO20: =IF(AND(D20<>"",AK20=0,AL20=0,AM20=0,AN20=0,AJ20<>0),1,"") | AR20: =AY15&" :" -> Present : | AS20: =_xlfn.XLOOKUP($AS$14,$D$14:$D$10001,$AJ$14:$AJ$10001,"-") -> 8 | BB20: Difference | BC20: =SUM(AK14:AN1001) -> 62
C21: 8 | D21: Jeevitha | X21: A | Y21: P | Z21: H | AA21: P | AB21: P | AC21: P | AD21: P | AE21: P | AF21: P | AG21: H | AH21: A | AI21: P | AJ21: =COUNTIF(E21:AI21,$AJ$13) -> 8 | AK21: =COUNTIF(E21:AI21,$AK$13) -> 2 | AL21: =COUNTIF(E21:AI21,$AL$13) -> 2 | AM21: =COUNTIF(E21:AI21,$AM$13) -> 0 | AN21: =COUNTIF(E21:AI21,$AN$13) -> 0 | AO21: =IF(AND(D21<>"",AK21=0,AL21=0,AM21=0,AN21=0,AJ21<>0),1,"") | AR21: =AY16&" :" -> Absent : | AS21: =_xlfn.XLOOKUP($AS$14,$D$14:$D$10001,$AK$14:$AK$10001,"-") -> 3 | BB21: Ratio | BC21: =IFERROR(BC19/SUM(BC19:BC20),"-") -> 0.71296296
C22: 9 | D22: Sujitha | X22: P | Y22: P | Z22: H | AA22: P | AB22: P | AC22: P | AD22: P | AE22: p | AF22: p | AG22: H | AH22: p | AI22: p | AJ22: =COUNTIF(E22:AI22,$AJ$13) -> 10 | AK22: =COUNTIF(E22:AI22,$AK$13) -> 0 | AL22: =COUNTIF(E22:AI22,$AL$13) -> 2 | AM22: =COUNTIF(E22:AI22,$AM$13) -> 0 | AN22: =COUNTIF(E22:AI22,$AN$13) -> 0 | AO22: =IF(AND(D22<>"",AK22=0,AL22=0,AM22=0,AN22=0,AJ22<>0),1,"") | AR22: =AY17&" :" -> Holiday : | AS22: =_xlfn.XLOOKUP($AS$14,$D$14:$D$10001,$AL$14:$AL$10001,"-") -> 1 | BB22: Full attendance | BC22: =COUNTIF(AO14:AO10001,1)&" People" -> 0 People
C23: 10 | D23: Swathi | X23: P | Y23: A | Z23: H | AA23: P | AB23: P | AC23: P | AD23: P | AE23: P | AF23: P | AG23: H | AH23: P | AI23: A | AJ23: =COUNTIF(E23:AI23,$AJ$13) -> 8 | AK23: =COUNTIF(E23:AI23,$AK$13) -> 2 | AL23: =COUNTIF(E23:AI23,$AL$13) -> 2 | AM23: =COUNTIF(E23:AI23,$AM$13) -> 0 | AN23: =COUNTIF(E23:AI23,$AN$13) -> 0 | AO23: =IF(AND(D23<>"",AK23=0,AL23=0,AM23=0,AN23=0,AJ23<>0),1,"") | AR23: =AY18&" :" -> Sick Leave : | AS23: =_xlfn.XLOOKUP($AS$14,$D$14:$D$10001,$AM$14:$AM$10001,"-") -> 0 | BB23: Number of employees | BC23: =COUNTA(D14:D10001)&" People" -> 15 People
C24: 11 | D24: Mathavi | X24: A | Y24: P | Z24: H | AA24: P | AB24: P | AC24: P | AD24: P | AE24: P | AF24: P | AG24: H | AH24: P | AI24: P | AJ24: =COUNTIF(E24:AI24,$AJ$13) -> 9 | AK24: =COUNTIF(E24:AI24,$AK$13) -> 1 | AL24: =COUNTIF(E24:AI24,$AL$13) -> 2 | AM24: =COUNTIF(E24:AI24,$AM$13) -> 0 | AN24: =COUNTIF(E24:AI24,$AN$13) -> 0 | AO24: =IF(AND(D24<>"",AK24=0,AL24=0,AM24=0,AN24=0,AJ24<>0),1,"") | AR24: =AY19&" :" -> Casual : | AS24: =_xlfn.XLOOKUP($AS$14,$D$14:$D$10001,$AN$14:$AN$10001,"-") -> 0
C25: 12 | D25: Deepa.T | X25: A | Y25: A | Z25: A | AA25: P | AB25: P | AC25: P | AD25: P | AE25: P | AF25: P | AG25: H | AH25: P | AI25: P | AJ25: =COUNTIF(E25:AI25,$AJ$13) -> 8 | AK25: =COUNTIF(E25:AI25,$AK$13) -> 3 | AL25: =COUNTIF(E25:AI25,$AL$13) -> 1 | AM25: =COUNTIF(E25:AI25,$AM$13) -> 0 | AN25: =COUNTIF(E25:AI25,$AN$13) -> 0 | AO25: =IF(AND(D25<>"",AK25=0,AL25=0,AM25=0,AN25=0,AJ25<>0),1,"")
C26: 13 | D26: Hema | X26: P | Y26: P | Z26: H | AA26: P | AB26: P | AC26: P | AD26: P | AE26: p | AF26: p | AG26: H | AH26: P | AI26: P | AJ26: =COUNTIF(E26:AI26,$AJ$13) -> 10 | AK26: =COUNTIF(E26:AI26,$AK$13) -> 0 | AL26: =COUNTIF(E26:AI26,$AL$13) -> 2 | AM26: =COUNTIF(E26:AI26,$AM$13) -> 0 | AN26: =COUNTIF(E26:AI26,$AN$13) -> 0 | AO26: =IF(AND(D26<>"",AK26=0,AL26=0,AM26=0,AN26=0,AJ26<>0),1,"")
C27: 14 | D27: Dharani | X27: A | Y27: A | Z27: A | AA27: A | AB27: A | AC27: A | AD27: P | AE27: P | AF27: P | AG27: H | AH27: P | AI27: P | AJ27: =COUNTIF(E27:AI27,$AJ$13) -> 5 | AK27: =COUNTIF(E27:AI27,$AK$13) -> 6 | AL27: =COUNTIF(E27:AI27,$AL$13) -> 1 | AM27: =COUNTIF(E27:AI27,$AM$13) -> 0 | AN27: =COUNTIF(E27:AI27,$AN$13) -> 0 | AO27: =IF(AND(D27<>"",AK27=0,AL27=0,AM27=0,AN27=0,AJ27<>0),1,"")
C28: 15 | D28: Barathi | X28: A | Y28: A | Z28: A | AA28: A | AB28: A | AC28: A | AD28: P | AE28: P | AF28: P | AG28: H | AH28: P | AI28: P | AJ28: =COUNTIF(E28:AI28,$AJ$13) -> 5 | AK28: =COUNTIF(E28:AI28,$AK$13) -> 6 | AL28: =COUNTIF(E28:AI28,$AL$13) -> 1 | AM28: =COUNTIF(E28:AI28,$AM$13) -> 0 | AN28: =COUNTIF(E28:AI28,$AN$13) -> 0 | AO28: =IF(AND(D28<>"",AK28=0,AL28=0,AM28=0,AN28=0,AJ28<>0),1,"")
AJ29: =COUNTIF(E29:AI29,$AJ$13) -> 0 | AK29: =COUNTIF(E29:AI29,$AK$13) -> 0 | AL29: =COUNTIF(E29:AI29,$AL$13) -> 0 | AM29: =COUNTIF(E29:AI29,$AM$13) -> 0 | AN29: =COUNTIF(E29:AI29,$AN$13) -> 0 | AO29: =IF(AND(D29<>"",AK29=0,AL29=0,AM29=0,AN29=0,AJ29<>0),1,"")
AJ30: =COUNTIF(E30:AI30,$AJ$13) -> 0 | AK30: =COUNTIF(E30:AI30,$AK$13) -> 0 | AL30: =COUNTIF(E30:AI30,$AL$13) -> 0 | AM30: =COUNTIF(E30:AI30,$AM$13) -> 0 | AN30: =COUNTIF(E30:AI30,$AN$13) -> 0 | AO30: =IF(AND(D30<>"",AK30=0,AL30=0,AM30=0,AN30=0,AJ30<>0),1,"")
AJ31: =COUNTIF(E31:AI31,$AJ$13) -> 0 | AK31: =COUNTIF(E31:AI31,$AK$13) -> 0 | AL31: =COUNTIF(E31:AI31,$AL$13) -> 0 | AM31: =COUNTIF(E31:AI31,$AM$13) -> 0 | AN31: =COUNTIF(E31:AI31,$AN$13) -> 0 | AO31: =IF(AND(D31<>"",AK31=0,AL31=0,AM31=0,AN31=0,AJ31<>0),1,"")
AJ32: =COUNTIF(E32:AI32,$AJ$13) -> 0 | AK32: =COUNTIF(E32:AI32,$AK$13) -> 0 | AL32: =COUNTIF(E32:AI32,$AL$13) -> 0 | AM32: =COUNTIF(E32:AI32,$AM$13) -> 0 | AN32: =COUNTIF(E32:AI32,$AN$13) -> 0 | AO32: =IF(AND(D32<>"",AK32=0,AL32=0,AM32=0,AN32=0,AJ32<>0),1,"")
AJ33: =COUNTIF(E33:AI33,$AJ$13) -> 0 | AK33: =COUNTIF(E33:AI33,$AK$13) -> 0 | AL33: =COUNTIF(E33:AI33,$AL$13) -> 0 | AM33: =COUNTIF(E33:AI33,$AM$13) -> 0 | AN33: =COUNTIF(E33:AI33,$AN$13) -> 0 | AO33: =IF(AND(D33<>"",AK33=0,AL33=0,AM33=0,AN33=0,AJ33<>0),1,"")
AJ34: =COUNTIF(E34:AI34,$AJ$13) -> 0 | AK34: =COUNTIF(E34:AI34,$AK$13) -> 0 | AL34: =COUNTIF(E34:AI34,$AL$13) -> 0 | AM34: =COUNTIF(E34:AI34,$AM$13) -> 0 | AN34: =COUNTIF(E34:AI34,$AN$13) -> 0 | AO34: =IF(AND(D34<>"",AK34=0,AL34=0,AM34=0,AN34=0,AJ34<>0),1,"")
AJ35: =COUNTIF(E35:AI35,$AJ$13) -> 0 | AK35: =COUNTIF(E35:AI35,$AK$13) -> 0 | AL35: =COUNTIF(E35:AI35,$AL$13) -> 0 | AM35: =COUNTIF(E35:AI35,$AM$13) -> 0 | AN35: =COUNTIF(E35:AI35,$AN$13) -> 0 | AO35: =IF(AND(D35<>"",AK35=0,AL35=0,AM35=0,AN35=0,AJ35<>0),1,"")
AJ36: =COUNTIF(E36:AI36,$AJ$13) -> 0 | AK36: =COUNTIF(E36:AI36,$AK$13) -> 0 | AL36: =COUNTIF(E36:AI36,$AL$13) -> 0 | AM36: =COUNTIF(E36:AI36,$AM$13) -> 0 | AN36: =COUNTIF(E36:AI36,$AN$13) -> 0 | AO36: =IF(AND(D36<>"",AK36=0,AL36=0,AM36=0,AN36=0,AJ36<>0),1,"")
AJ37: =COUNTIF(E37:AI37,$AJ$13) -> 0 | AK37: =COUNTIF(E37:AI37,$AK$13) -> 0 | AL37: =COUNTIF(E37:AI37,$AL$13) -> 0 | AM37: =COUNTIF(E37:AI37,$AM$13) -> 0 | AN37: =COUNTIF(E37:AI37,$AN$13) -> 0 | AO37: =IF(AND(D37<>"",AK37=0,AL37=0,AM37=0,AN37=0,AJ37<>0),1,"")
AJ38: =COUNTIF(E38:AI38,$AJ$13) -> 0 | AK38: =COUNTIF(E38:AI38,$AK$13) -> 0 | AL38: =COUNTIF(E38:AI38,$AL$13) -> 0 | AM38: =COUNTIF(E38:AI38,$AM$13) -> 0 | AN38: =COUNTIF(E38:AI38,$AN$13) -> 0 | AO38: =IF(AND(D38<>"",AK38=0,AL38=0,AM38=0,AN38=0,AJ38<>0),1,"")
AJ39: =COUNTIF(E39:AI39,$AJ$13) -> 0 | AK39: =COUNTIF(E39:AI39,$AK$13) -> 0 | AL39: =COUNTIF(E39:AI39,$AL$13) -> 0 | AM39: =COUNTIF(E39:AI39,$AM$13) -> 0 | AN39: =COUNTIF(E39:AI39,$AN$13) -> 0 | AO39: =IF(AND(D39<>"",AK39=0,AL39=0,AM39=0,AN39=0,AJ39<>0),1,"")
AJ40: =COUNTIF(E40:AI40,$AJ$13) -> 0 | AK40: =COUNTIF(E40:AI40,$AK$13) -> 0 | AL40: =COUNTIF(E40:AI40,$AL$13) -> 0 | AM40: =COUNTIF(E40:AI40,$AM$13) -> 0 | AN40: =COUNTIF(E40:AI40,$AN$13) -> 0 | AO40: =IF(AND(D40<>"",AK40=0,AL40=0,AM40=0,AN40=0,AJ40<>0),1,"")
... AJ1001: =COUNTIF(E1001:AI1001,$AJ$13) -> 0 | AK1001: =COUNTIF(E1001:AI1001,$AK$13) -> 0 | AL1001: =COUNTIF(E1001:AI1001,$AL$13) -> 0 | AM1001: =COUNTIF(E1001:AI1001,$AM$13) -> 0 | AN1001: =COUNTIF(E1001:AI1001,$AN$13) -> 0 | AO1001: =IF(AND(D1001<>"",AK1001=0,AL1001=0,AM1001=0,AN1001=0,AJ1001<>0),1,"")

Sheet 4
C2: Employee Attendance Tracker
AR6: Statistical Year： | AS6: ='2'!AS6 -> 2026
AR8: Statistical Month： | AS8: 4
C10: Attendance Record
E11: =IF(E12="","",COUNTIF(E14:E10001,$AJ$13)) -> 12 | F11: =IF(F12="","",COUNTIF(F14:F10001,$AJ$13)) -> 14 | G11: =IF(G12="","",COUNTIF(G14:G10001,$AJ$13)) -> 13 | H11: =IF(H12="","",COUNTIF(H14:H10001,$AJ$13)) -> 14 | I11: =IF(I12="","",COUNTIF(I14:I10001,$AJ$13)) -> 0 | J11: =IF(J12="","",COUNTIF(J14:J10001,$AJ$13)) -> 12 | K11: =IF(K12="","",COUNTIF(K14:K10001,$AJ$13)) -> 12 | L11: =IF(L12="","",COUNTIF(L14:L10001,$AJ$13)) -> 15 | ... AI11: =IF(AI12="","",COUNTIF(AI14:AI10001,$AJ$13))
C12: No. | D12: Name | E12: =DATE($AS$6,$AS$8,1) -> 46113 | F12: =IFERROR(IF(MONTH(E12+1)<>$AS$8,"",E12+1),"") -> 46114 | G12: =IFERROR(IF(MONTH(F12+1)<>$AS$8,"",F12+1),"") -> 46115 | H12: =IFERROR(IF(MONTH(G12+1)<>$AS$8,"",G12+1),"") -> 46116 | I12: =IFERROR(IF(MONTH(H12+1)<>$AS$8,"",H12+1),"") -> 46117 | J12: =IFERROR(IF(MONTH(I12+1)<>$AS$8,"",I12+1),"") -> 46118 | K12: =IFERROR(IF(MONTH(J12+1)<>$AS$8,"",J12+1),"") -> 46119 | L12: =IFERROR(IF(MONTH(K12+1)<>$AS$8,"",K12+1),"") -> 46120 | M12: =IFERROR(IF(MONTH(L12+1)<>$AS$8,"",L12+1),"") -> 46121 | ... AI12: =IFERROR(IF(MONTH(AH12+1)<>$AS$8,"",AH12+1),"") | AJ12: Totals | AR12: Employee Query | AY12: Menu Custom
AJ13: ='4'!AZ15 -> P | AK13: ='4'!AZ16 -> A | AL13: ='4'!AZ17 -> H | AM13: ='4'!AZ18 -> SL | AN13: ='4'!AZ19 -> CL
C14: 1 | D14: Jeyanandhini | E14: P | F14: P | G14: P | H14: P | I14: H | J14: P | K14: P | L14: P | M14: P | N14: P | O14: P | P14: H | Q14: P | R14: H | S14: P | T14: P | U14: P | V14: P | W14: P | X14: P | Y14: P | Z14: P | AA14: H | AB14: P | AC14: P | AD14: H | AE14: P | AF14: P | AG14: P | AH14: P | AJ14: =COUNTIF(E14:AI14,$AJ$13) -> 25 | AK14: =COUNTIF(E14:AI14,$AK$13) -> 0 | AL14: =COUNTIF(E14:AI14,$AL$13) -> 5 | AM14: =COUNTIF(E14:AI14,$AM$13) -> 0 | AN14: =COUNTIF(E14:AI14,$AN$13) -> 0 | AO14: =IF(AND(D14<>"",AK14=0,AL14=0,AM14=0,AN14=0,AJ14<>0),1,"") | AR14: Employee： | AS14: Deepa.T | AY14: Mean | AZ14: Display | BB14: Query： | BC14: =AS14 -> Deepa.T
C15: 2 | D15: Anusuya | E15: P | F15: P | G15: P | H15: P | I15: H | J15: P | K15: P | L15: P | M15: P | N15: P | O15: P | P15: H | Q15: P | R15: H | S15: P | T15: P | U15: A | V15: P | W15: P | X15: P | Y15: P | Z15: P | AA15: H | AB15: P | AC15: P | AD15: H | AE15: P | AF15: P | AG15: P | AH15: P | AJ15: =COUNTIF(E15:AI15,$AJ$13) -> 24 | AK15: =COUNTIF(E15:AI15,$AK$13) -> 1 | AL15: =COUNTIF(E15:AI15,$AL$13) -> 5 | AM15: =COUNTIF(E15:AI15,$AM$13) -> 0 | AN15: =COUNTIF(E15:AI15,$AN$13) -> 0 | AO15: =IF(AND(D15<>"",AK15=0,AL15=0,AM15=0,AN15=0,AJ15<>0),1,"") | AY15: Present | AZ15: P | BB15: No. | BC15: =_xlfn.XLOOKUP($AS$14,$D$14:$D$10001,$C$14:$C$10001,"-") -> 12
C16: 3 | D16: Lakshmipriya | E16: A | F16: A | G16: A | H16: A | I16: H | J16: A | K16: A | L16: P | M16: P | N16: P | O16: P | P16: H | Q16: P | R16: H | S16: P | T16: P | U16: P | V16: P | W16: P | X16: P | Y16: P | Z16: P | AA16: H | AB16: P | AC16: A | AD16: H | AE16: H | AF16: H | AG16: H | AH16: H | AJ16: =COUNTIF(E16:AI16,$AJ$13) -> 14 | AK16: =COUNTIF(E16:AI16,$AK$13) -> 7 | AL16: =COUNTIF(E16:AI16,$AL$13) -> 9 | AM16: =COUNTIF(E16:AI16,$AM$13) -> 0 | AN16: =COUNTIF(E16:AI16,$AN$13) -> 0 | AO16: =IF(AND(D16<>"",AK16=0,AL16=0,AM16=0,AN16=0,AJ16<>0),1,"") | AY16: Absent | AZ16: A | BB16: Attendance Ratio | BC16: =IFERROR(AS20/SUM($AS$20:$AS$24),"-") -> 0.6
C17: 4 | D17: Varshini | E17: P | F17: P | G17: A | H17: P | I17: H | J17: A | K17: A | L17: P | M17: P | N17: P | O17: P | P17: H | Q17: P | R17: H | S17: P | T17: P | U17: P | V17: P | W17: P | X17: P | Y17: P | Z17: P | AA17: H | AB17: P | AC17: A | AD17: H | AE17: H | AF17: H | AG17: H | AH17: H | AJ17: =COUNTIF(E17:AI17,$AJ$13) -> 17 | AK17: =COUNTIF(E17:AI17,$AK$13) -> 4 | AL17: =COUNTIF(E17:AI17,$AL$13) -> 9 | AM17: =COUNTIF(E17:AI17,$AM$13) -> 0 | AN17: =COUNTIF(E17:AI17,$AN$13) -> 0 | AO17: =IF(AND(D17<>"",AK17=0,AL17=0,AM17=0,AN17=0,AJ17<>0),1,"") | AY17: Holiday | AZ17: H
C18: 5 | D18: Kaleeswari | E18: A | F18: P | G18: P | H18: P | I18: H | J18: P | K18: P | L18: P | M18: P | N18: P | O18: P | P18: H | Q18: P | R18: H | S18: P | T18: P | U18: P | V18: P | W18: P | X18: P | Y18: P | Z18: P | AA18: H | AB18: P | AC18: A | AD18: H | AE18: H | AF18: H | AG18: H | AH18: H | AJ18: =COUNTIF(E18:AI18,$AJ$13) -> 19 | AK18: =COUNTIF(E18:AI18,$AK$13) -> 2 | AL18: =COUNTIF(E18:AI18,$AL$13) -> 9 | AM18: =COUNTIF(E18:AI18,$AM$13) -> 0 | AN18: =COUNTIF(E18:AI18,$AN$13) -> 0 | AO18: =IF(AND(D18<>"",AK18=0,AL18=0,AM18=0,AN18=0,AJ18<>0),1,"") | AY18: Sick Leave | AZ18: SL
C19: 6 | D19: Priyadharshini | E19: A | F19: P | G19: P | H19: P | I19: H | J19: P | K19: P | L19: P | M19: P | N19: P | O19: P | P19: H | Q19: P | R19: H | S19: P | T19: P | U19: P | V19: P | W19: P | X19: P | Y19: P | Z19: P | AA19: H | AB19: P | AC19: A | AD19: H | AE19: H | AF19: H | AG19: H | AH19: H | AJ19: =COUNTIF(E19:AI19,$AJ$13) -> 19 | AK19: =COUNTIF(E19:AI19,$AK$13) -> 2 | AL19: =COUNTIF(E19:AI19,$AL$13) -> 9 | AM19: =COUNTIF(E19:AI19,$AM$13) -> 0 | AN19: =COUNTIF(E19:AI19,$AN$13) -> 0 | AO19: =IF(AND(D19<>"",AK19=0,AL19=0,AM19=0,AN19=0,AJ19<>0),1,"") | AY19: Casual | AZ19: CL | BB19: Present Total | BC19: =SUM(AJ14:AJ1001) -> 347
C20: 7 | D20: Gayathri | E20: P | F20: P | G20: P | H20: P | I20: H | J20: P | K20: P | L20: P | M20: P | N20: P | O20: P | P20: H | Q20: P | R20: H | S20: P | T20: P | U20: P | V20: P | W20: P | X20: A | Y20: P | Z20: P | AA20: H | AB20: P | AC20: A | AD20: H | AE20: H | AF20: H | AG20: H | AH20: H | AJ20: =COUNTIF(E20:AI20,$AJ$13) -> 19 | AK20: =COUNTIF(E20:AI20,$AK$13) -> 2 | AL20: =COUNTIF(E20:AI20,$AL$13) -> 9 | AM20: =COUNTIF(E20:AI20,$AM$13) -> 0 | AN20: =COUNTIF(E20:AI20,$AN$13) -> 0 | AO20: =IF(AND(D20<>"",AK20=0,AL20=0,AM20=0,AN20=0,AJ20<>0),1,"") | AR20: =AY15&" :" -> Present : | AS20: =_xlfn.XLOOKUP($AS$14,$D$14:$D$10001,$AJ$14:$AJ$10001,"-") -> 18 | BB20: Difference | BC20: =SUM(AK14:AN1001) -> 239
C21: 8 | D21: Jeevitha | E21: P | F21: P | G21: P | H21: P | I21: H | J21: P | K21: P | L21: P | M21: P | N21: P | O21: P | P21: H | Q21: A | R21: H | S21: P | T21: P | U21: P | V21: P | W21: P | X21: P | Y21: A | Z21: A | AA21: H | AB21: P | AC21: A | AD21: H | AE21: H | AF21: H | AG21: H | AH21: H | AJ21: =COUNTIF(E21:AI21,$AJ$13) -> 17 | AK21: =COUNTIF(E21:AI21,$AK$13) -> 4 | AL21: =COUNTIF(E21:AI21,$AL$13) -> 9 | AM21: =COUNTIF(E21:AI21,$AM$13) -> 0 | AN21: =COUNTIF(E21:AI21,$AN$13) -> 0 | AO21: =IF(AND(D21<>"",AK21=0,AL21=0,AM21=0,AN21=0,AJ21<>0),1,"") | AR21: =AY16&" :" -> Absent : | AS21: =_xlfn.XLOOKUP($AS$14,$D$14:$D$10001,$AK$14:$AK$10001,"-") -> 3 | BB21: Ratio | BC21: =IFERROR(BC19/SUM(BC19:BC20),"-") -> 0.59215017
C22: 9 | D22: Sujitha | E22: P | F22: P | G22: P | H22: P | I22: H | J22: P | K22: P | L22: P | M22: P | N22: P | O22: A | P22: H | Q22: P | R22: H | S22: P | T22: P | U22: P | V22: P | W22: P | X22: P | Y22: P | Z22: A | AA22: H | AB22: P | AC22: A | AD22: H | AE22: H | AF22: H | AG22: H | AH22: H | AJ22: =COUNTIF(E22:AI22,$AJ$13) -> 18 | AK22: =COUNTIF(E22:AI22,$AK$13) -> 3 | AL22: =COUNTIF(E22:AI22,$AL$13) -> 9 | AM22: =COUNTIF(E22:AI22,$AM$13) -> 0 | AN22: =COUNTIF(E22:AI22,$AN$13) -> 0 | AO22: =IF(AND(D22<>"",AK22=0,AL22=0,AM22=0,AN22=0,AJ22<>0),1,"") | AR22: =AY17&" :" -> Holiday : | AS22: =_xlfn.XLOOKUP($AS$14,$D$14:$D$10001,$AL$14:$AL$10001,"-") -> 9 | BB22: Full attendance | BC22: =COUNTIF(AO14:AO10001,1)&" People" -> 0 People
C23: 10 | D23: Swathi | E23: P | F23: P | G23: P | H23: P | I23: H | J23: P | K23: P | L23: P | M23: P | N23: P | O23: P | P23: H | Q23: P | R23: H | S23: P | T23: P | U23: P | V23: P | W23: P | X23: P | Y23: P | Z23: P | AA23: H | AB23: P | AC23: P | AD23: H | AE23: H | AF23: H | AG23: H | AH23: H | AJ23: =COUNTIF(E23:AI23,$AJ$13) -> 21 | AK23: =COUNTIF(E23:AI23,$AK$13) -> 0 | AL23: =COUNTIF(E23:AI23,$AL$13) -> 9 | AM23: =COUNTIF(E23:AI23,$AM$13) -> 0 | AN23: =COUNTIF(E23:AI23,$AN$13) -> 0 | AO23: =IF(AND(D23<>"",AK23=0,AL23=0,AM23=0,AN23=0,AJ23<>0),1,"") | AR23: =AY18&" :" -> Sick Leave : | AS23: =_xlfn.XLOOKUP($AS$14,$D$14:$D$10001,$AM$14:$AM$10001,"-") -> 0 | BB23: Number of employees | BC23: =COUNTA(D14:D10001)&" People" -> 21 People
C24: 11 | D24: Mathavi | E24: P | F24: P | G24: P | H24: P | I24: H | J24: P | K24: P | L24: P | M24: P | N24: P | O24: P | P24: H | Q24: A | R24: H | S24: A | T24: P | U24: P | V24: P | W24: P | X24: P | Y24: P | Z24: P | AA24: H | AB24: P | AC24: A | AD24: H | AE24: H | AF24: H | AG24: H | AH24: H | AJ24: =COUNTIF(E24:AI24,$AJ$13) -> 18 | AK24: =COUNTIF(E24:AI24,$AK$13) -> 3 | AL24: =COUNTIF(E24:AI24,$AL$13) -> 9 | AM24: =COUNTIF(E24:AI24,$AM$13) -> 0 | AN24: =COUNTIF(E24:AI24,$AN$13) -> 0 | AO24: =IF(AND(D24<>"",AK24=0,AL24=0,AM24=0,AN24=0,AJ24<>0),1,"") | AR24: =AY19&" :" -> Casual : | AS24: =_xlfn.XLOOKUP($AS$14,$D$14:$D$10001,$AN$14:$AN$10001,"-") -> 0
C25: 12 | D25: Deepa.T | E25: P | F25: P | G25: P | H25: P | I25: H | J25: A | K25: A | L25: P | M25: P | N25: P | O25: P | P25: H | Q25: P | R25: H | S25: P | T25: P | U25: P | V25: P | W25: P | X25: P | Y25: P | Z25: P | AA25: H | AB25: P | AC25: A | AD25: H | AE25: H | AF25: H | AG25: H | AH25: H | AJ25: =COUNTIF(E25:AI25,$AJ$13) -> 18 | AK25: =COUNTIF(E25:AI25,$AK$13) -> 3 | AL25: =COUNTIF(E25:AI25,$AL$13) -> 9 | AM25: =COUNTIF(E25:AI25,$AM$13) -> 0 | AN25: =COUNTIF(E25:AI25,$AN$13) -> 0 | AO25: =IF(AND(D25<>"",AK25=0,AL25=0,AM25=0,AN25=0,AJ25<>0),1,"")
C26: 13 | D26: Hema | E26: P | F26: P | G26: P | H26: P | I26: H | J26: P | K26: P | L26: P | M26: P | N26: P | O26: P | P26: H | Q26: P | R26: H | S26: P | T26: P | U26: P | V26: A | W26: P | X26: P | Y26: P | Z26: P | AA26: H | AB26: P | AC26: A | AD26: H | AE26: H | AF26: H | AG26: H | AH26: H | AJ26: =COUNTIF(E26:AI26,$AJ$13) -> 19 | AK26: =COUNTIF(E26:AI26,$AK$13) -> 2 | AL26: =COUNTIF(E26:AI26,$AL$13) -> 9 | AM26: =COUNTIF(E26:AI26,$AM$13) -> 0 | AN26: =COUNTIF(E26:AI26,$AN$13) -> 0 | AO26: =IF(AND(D26<>"",AK26=0,AL26=0,AM26=0,AN26=0,AJ26<>0),1,"")
C27: 14 | D27: Dharani | E27: P | F27: P | G27: P | H27: P | I27: H | J27: P | K27: P | L27: P | M27: P | N27: P | O27: P | P27: H | Q27: P | R27: H | S27: P | T27: P | U27: P | V27: P | W27: P | X27: P | Y27: P | Z27: P | AA27: H | AB27: P | AC27: A | AD27: H | AE27: H | AF27: H | AG27: H | AH27: H | AJ27: =COUNTIF(E27:AI27,$AJ$13) -> 20 | AK27: =COUNTIF(E27:AI27,$AK$13) -> 1 | AL27: =COUNTIF(E27:AI27,$AL$13) -> 9 | AM27: =COUNTIF(E27:AI27,$AM$13) -> 0 | AN27: =COUNTIF(E27:AI27,$AN$13) -> 0 | AO27: =IF(AND(D27<>"",AK27=0,AL27=0,AM27=0,AN27=0,AJ27<>0),1,"")
C28: 15 | D28: Barathi | E28: P | F28: P | G28: P | H28: P | I28: H | J28: P | K28: P | L28: A | M28: P | N28: P | O28: P | P28: H | Q28: P | R28: H | S28: P | T28: P | U28: P | V28: P | W28: P | X28: P | Y28: P | Z28: P | AA28: H | AB28: P | AC28: A | AD28: H | AE28: H | AF28: H | AG28: H | AH28: H | AJ28: =COUNTIF(E28:AI28,$AJ$13) -> 19 | AK28: =COUNTIF(E28:AI28,$AK$13) -> 2 | AL28: =COUNTIF(E28:AI28,$AL$13) -> 9 | AM28: =COUNTIF(E28:AI28,$AM$13) -> 0 | AN28: =COUNTIF(E28:AI28,$AN$13) -> 0 | AO28: =IF(AND(D28<>"",AK28=0,AL28=0,AM28=0,AN28=0,AJ28<>0),1,"")
C29: 16 | D29: Anngeeswari | E29: A | F29: A | G29: A | H29: A | I29: A | J29: A | K29: A | L29: P | M29: P | N29: P | O29: P | P29: H | Q29: P | R29: H | S29: P | T29: P | U29: P | V29: P | W29: P | X29: P | Y29: P | Z29: P | AA29: H | AB29: P | AC29: P | AD29: H | AE29: H | AF29: H | AG29: H | AH29: H | AJ29: =COUNTIF(E29:AI29,$AJ$13) -> 15 | AK29: =COUNTIF(E29:AI29,$AK$13) -> 7 | AL29: =COUNTIF(E29:AI29,$AL$13) -> 8 | AM29: =COUNTIF(E29:AI29,$AM$13) -> 0 | AN29: =COUNTIF(E29:AI29,$AN$13) -> 0 | AO29: =IF(AND(D29<>"",AK29=0,AL29=0,AM29=0,AN29=0,AJ29<>0),1,"")
C30: 17 | D30: Reshma | E30: A | F30: A | G30: A | H30: A | I30: A | J30: A | K30: A | L30: A | M30: P | N30: P | O30: P | P30: H | Q30: P | R30: H | S30: P | T30: P | U30: P | V30: P | W30: P | X30: P | Y30: P | Z30: P | AA30: H | AB30: A | AC30: A | AD30: H | AE30: H | AF30: H | AG30: H | AH30: H | AJ30: =COUNTIF(E30:AI30,$AJ$13) -> 12 | AK30: =COUNTIF(E30:AI30,$AK$13) -> 10 | AL30: =COUNTIF(E30:AI30,$AL$13) -> 8 | AM30: =COUNTIF(E30:AI30,$AM$13) -> 0 | AN30: =COUNTIF(E30:AI30,$AN$13) -> 0 | AO30: =IF(AND(D30<>"",AK30=0,AL30=0,AM30=0,AN30=0,AJ30<>0),1,"")
D31: Pandiselvi | P31: H | Q31: A | R31: H | S31: A | T31: A | U31: A | V31: A | W31: A | X31: P | Y31: A | Z31: P | AA31: H | AB31: P | AC31: A | AD31: H | AE31: H | AF31: H | AG31: H | AH31: H | AJ31: =COUNTIF(E31:AI31,$AJ$13) -> 3 | AK31: =COUNTIF(E31:AI31,$AK$13) -> 8 | AL31: =COUNTIF(E31:AI31,$AL$13) -> 8 | AM31: =COUNTIF(E31:AI31,$AM$13) -> 0 | AN31: =COUNTIF(E31:AI31,$AN$13) -> 0 | AO31: =IF(AND(D31<>"",AK31=0,AL31=0,AM31=0,AN31=0,AJ31<>0),1,"")
D32: Karthika | P32: H | Q32: P | R32: H | S32: P | T32: P | U32: P | V32: P | W32: P | X32: P | Y32: P | Z32: P | AA32: H | AB32: P | AC32: P | AD32: H | AE32: H | AF32: H | AG32: H | AH32: H | AJ32: =COUNTIF(E32:AI32,$AJ$13) -> 11 | AK32: =COUNTIF(E32:AI32,$AK$13) -> 0 | AL32: =COUNTIF(E32:AI32,$AL$13) -> 8 | AM32: =COUNTIF(E32:AI32,$AM$13) -> 0 | AN32: =COUNTIF(E32:AI32,$AN$13) -> 0 | AO32: =IF(AND(D32<>"",AK32=0,AL32=0,AM32=0,AN32=0,AJ32<>0),1,"")
D33: Nithiya | P33: H | Q33: P | R33: H | S33: P | T33: P | U33: P | V33: P | W33: P | X33: P | Y33: P | Z33: P | AA33: H | AB33: P | AC33: P | AD33: H | AE33: H | AF33: H | AG33: H | AH33: H | AJ33: =COUNTIF(E33:AI33,$AJ$13) -> 11 | AK33: =COUNTIF(E33:AI33,$AK$13) -> 0 | AL33: =COUNTIF(E33:AI33,$AL$13) -> 8 | AM33: =COUNTIF(E33:AI33,$AM$13) -> 0 | AN33: =COUNTIF(E33:AI33,$AN$13) -> 0 | AO33: =IF(AND(D33<>"",AK33=0,AL33=0,AM33=0,AN33=0,AJ33<>0),1,"")
D34: Deepa.M | P34: H | Q34: P | R34: H | S34: P | T34: P | U34: P | V34: P | W34: P | X34: P | Y34: A | Z34: A | AA34: H | AB34: A | AC34: P | AD34: H | AE34: H | AF34: H | AG34: H | AH34: H | AJ34: =COUNTIF(E34:AI34,$AJ$13) -> 8 | AK34: =COUNTIF(E34:AI34,$AK$13) -> 3 | AL34: =COUNTIF(E34:AI34,$AL$13) -> 8 | AM34: =COUNTIF(E34:AI34,$AM$13) -> 0 | AN34: =COUNTIF(E34:AI34,$AN$13) -> 0 | AO34: =IF(AND(D34<>"",AK34=0,AL34=0,AM34=0,AN34=0,AJ34<>0),1,"")
AJ35: =COUNTIF(E35:AI35,$AJ$13) -> 0 | AK35: =COUNTIF(E35:AI35,$AK$13) -> 0 | AL35: =COUNTIF(E35:AI35,$AL$13) -> 0 | AM35: =COUNTIF(E35:AI35,$AM$13) -> 0 | AN35: =COUNTIF(E35:AI35,$AN$13) -> 0 | AO35: =IF(AND(D35<>"",AK35=0,AL35=0,AM35=0,AN35=0,AJ35<>0),1,"")
AJ36: =COUNTIF(E36:AI36,$AJ$13) -> 0 | AK36: =COUNTIF(E36:AI36,$AK$13) -> 0 | AL36: =COUNTIF(E36:AI36,$AL$13) -> 0 | AM36: =COUNTIF(E36:AI36,$AM$13) -> 0 | AN36: =COUNTIF(E36:AI36,$AN$13) -> 0 | AO36: =IF(AND(D36<>"",AK36=0,AL36=0,AM36=0,AN36=0,AJ36<>0),1,"")
AJ37: =COUNTIF(E37:AI37,$AJ$13) -> 0 | AK37: =COUNTIF(E37:AI37,$AK$13) -> 0 | AL37: =COUNTIF(E37:AI37,$AL$13) -> 0 | AM37: =COUNTIF(E37:AI37,$AM$13) -> 0 | AN37: =COUNTIF(E37:AI37,$AN$13) -> 0 | AO37: =IF(AND(D37<>"",AK37=0,AL37=0,AM37=0,AN37=0,AJ37<>0),1,"")
AJ38: =COUNTIF(E38:AI38,$AJ$13) -> 0 | AK38: =COUNTIF(E38:AI38,$AK$13) -> 0 | AL38: =COUNTIF(E38:AI38,$AL$13) -> 0 | AM38: =COUNTIF(E38:AI38,$AM$13) -> 0 | AN38: =COUNTIF(E38:AI38,$AN$13) -> 0 | AO38: =IF(AND(D38<>"",AK38=0,AL38=0,AM38=0,AN38=0,AJ38<>0),1,"")
AJ39: =COUNTIF(E39:AI39,$AJ$13) -> 0 | AK39: =COUNTIF(E39:AI39,$AK$13) -> 0 | AL39: =COUNTIF(E39:AI39,$AL$13) -> 0 | AM39: =COUNTIF(E39:AI39,$AM$13) -> 0 | AN39: =COUNTIF(E39:AI39,$AN$13) -> 0 | AO39: =IF(AND(D39<>"",AK39=0,AL39=0,AM39=0,AN39=0,AJ39<>0),1,"")
AJ40: =COUNTIF(E40:AI40,$AJ$13) -> 0 | AK40: =COUNTIF(E40:AI40,$AK$13) -> 0 | AL40: =COUNTIF(E40:AI40,$AL$13) -> 0 | AM40: =COUNTIF(E40:AI40,$AM$13) -> 0 | AN40: =COUNTIF(E40:AI40,$AN$13) -> 0 | AO40: =IF(AND(D40<>"",AK40=0,AL40=0,AM40=0,AN40=0,AJ40<>0),1,"")
AJ41: =COUNTIF(E41:AI41,$AJ$13) -> 0 | AK41: =COUNTIF(E41:AI41,$AK$13) -> 0 | AL41: =COUNTIF(E41:AI41,$AL$13) -> 0 | AM41: =COUNTIF(E41:AI41,$AM$13) -> 0 | AN41: =COUNTIF(E41:AI41,$AN$13) -> 0 | AO41: =IF(AND(D41<>"",AK41=0,AL41=0,AM41=0,AN41=0,AJ41<>0),1,"")
AJ42: =COUNTIF(E42:AI42,$AJ$13) -> 0 | AK42: =COUNTIF(E42:AI42,$AK$13) -> 0 | AL42: =COUNTIF(E42:AI42,$AL$13) -> 0 | AM42: =COUNTIF(E42:AI42,$AM$13) -> 0 | AN42: =COUNTIF(E42:AI42,$AN$13) -> 0 | AO42: =IF(AND(D42<>"",AK42=0,AL42=0,AM42=0,AN42=0,AJ42<>0),1,"")
AJ43: =COUNTIF(E43:AI43,$AJ$13) -> 0 | AK43: =COUNTIF(E43:AI43,$AK$13) -> 0 | AL43: =COUNTIF(E43:AI43,$AL$13) -> 0 | AM43: =COUNTIF(E43:AI43,$AM$13) -> 0 | AN43: =COUNTIF(E43:AI43,$AN$13) -> 0 | AO43: =IF(AND(D43<>"",AK43=0,AL43=0,AM43=0,AN43=0,AJ43<>0),1,"")
AJ44: =COUNTIF(E44:AI44,$AJ$13) -> 0 | AK44: =COUNTIF(E44:AI44,$AK$13) -> 0 | AL44: =COUNTIF(E44:AI44,$AL$13) -> 0 | AM44: =COUNTIF(E44:AI44,$AM$13) -> 0 | AN44: =COUNTIF(E44:AI44,$AN$13) -> 0 | AO44: =IF(AND(D44<>"",AK44=0,AL44=0,AM44=0,AN44=0,AJ44<>0),1,"")
AJ45: =COUNTIF(E45:AI45,$AJ$13) -> 0 | AK45: =COUNTIF(E45:AI45,$AK$13) -> 0 | AL45: =COUNTIF(E45:AI45,$AL$13) -> 0 | AM45: =COUNTIF(E45:AI45,$AM$13) -> 0 | AN45: =COUNTIF(E45:AI45,$AN$13) -> 0 | AO45: =IF(AND(D45<>"",AK45=0,AL45=0,AM45=0,AN45=0,AJ45<>0),1,"")
AJ46: =COUNTIF(E46:AI46,$AJ$13) -> 0 | AK46: =COUNTIF(E46:AI46,$AK$13) -> 0 | AL46: =COUNTIF(E46:AI46,$AL$13) -> 0 | AM46: =COUNTIF(E46:AI46,$AM$13) -> 0 | AN46: =COUNTIF(E46:AI46,$AN$13) -> 0 | AO46: =IF(AND(D46<>"",AK46=0,AL46=0,AM46=0,AN46=0,AJ46<>0),1,"")
...

Sheet 5
C2: Employee Attendance Tracker
AR6: Statistical Year： | AS6: ='2'!AS6 -> 2026
AR8: Statistical Month： | AS8: 5
C10: Attendance Record
E11: =IF(E12="","",COUNTIF(E14:E10001,$AJ$13)) -> 0 | F11: =IF(F12="","",COUNTIF(F14:F10001,$AJ$13)) -> 2 | G11: =IF(G12="","",COUNTIF(G14:G10001,$AJ$13)) -> 0 | H11: =IF(H12="","",COUNTIF(H14:H10001,$AJ$13)) -> 0 | I11: =IF(I12="","",COUNTIF(I14:I10001,$AJ$13)) -> 0 | J11: =IF(J12="","",COUNTIF(J14:J10001,$AJ$13)) -> 0 | K11: =IF(K12="","",COUNTIF(K14:K10001,$AJ$13)) -> 0 | L11: =IF(L12="","",COUNTIF(L14:L10001,$AJ$13)) -> 0 | ... AI11: =IF(AI12="","",COUNTIF(AI14:AI10001,$AJ$13)) -> 0
C12: No. | D12: Name | E12: =DATE($AS$6,$AS$8,1) -> 46143 | F12: =IFERROR(IF(MONTH(E12+1)<>$AS$8,"",E12+1),"") -> 46144 | G12: =IFERROR(IF(MONTH(F12+1)<>$AS$8,"",F12+1),"") -> 46145 | H12: =IFERROR(IF(MONTH(G12+1)<>$AS$8,"",G12+1),"") -> 46146 | I12: =IFERROR(IF(MONTH(H12+1)<>$AS$8,"",H12+1),"") -> 46147 | J12: =IFERROR(IF(MONTH(I12+1)<>$AS$8,"",I12+1),"") -> 46148 | K12: =IFERROR(IF(MONTH(J12+1)<>$AS$8,"",J12+1),"") -> 46149 | L12: =IFERROR(IF(MONTH(K12+1)<>$AS$8,"",K12+1),"") -> 46150 | M12: =IFERROR(IF(MONTH(L12+1)<>$AS$8,"",L12+1),"") -> 46151 | ... AI12: =IFERROR(IF(MONTH(AH12+1)<>$AS$8,"",AH12+1),"") -> 46173 | AJ12: Totals | AR12: Employee Query | AY12: Menu Custom
AJ13: ='5'!AZ15 -> P | AK13: ='5'!AZ16 -> A | AL13: ='5'!AZ17 -> H | AM13: ='5'!AZ18 -> SL | AN13: ='5'!AZ19 -> CL
C14: 1 | D14: ANUSUYA | E14: H | F14: P | AJ14: =COUNTIF(E14:AI14,$AJ$13) -> 1 | AK14: =COUNTIF(E14:AI14,$AK$13) -> 0 | AL14: =COUNTIF(E14:AI14,$AL$13) -> 1 | AM14: =COUNTIF(E14:AI14,$AM$13) -> 0 | AN14: =COUNTIF(E14:AI14,$AN$13) -> 0 | AO14: =IF(AND(D14<>"",AK14=0,AL14=0,AM14=0,AN14=0,AJ14<>0),1,"") | AR14: Employee： | AY14: Mean | AZ14: Display | BB14: Query： | BC14: =AS14 -> 0
C15: 2 | D15: JEYANANDHINI | E15: H | F15: P | AJ15: =COUNTIF(E15:AI15,$AJ$13) -> 1 | AK15: =COUNTIF(E15:AI15,$AK$13) -> 0 | AL15: =COUNTIF(E15:AI15,$AL$13) -> 1 | AM15: =COUNTIF(E15:AI15,$AM$13) -> 0 | AN15: =COUNTIF(E15:AI15,$AN$13) -> 0 | AO15: =IF(AND(D15<>"",AK15=0,AL15=0,AM15=0,AN15=0,AJ15<>0),1,"") | AY15: Present | AZ15: P | BB15: No. | BC15: =_xlfn.XLOOKUP($AS$14,$D$14:$D$10001,$C$14:$C$10001,"-") -> 0
AJ16: =COUNTIF(E16:AI16,$AJ$13) -> 0 | AK16: =COUNTIF(E16:AI16,$AK$13) -> 0 | AL16: =COUNTIF(E16:AI16,$AL$13) -> 0 | AM16: =COUNTIF(E16:AI16,$AM$13) -> 0 | AN16: =COUNTIF(E16:AI16,$AN$13) -> 0 | AO16: =IF(AND(D16<>"",AK16=0,AL16=0,AM16=0,AN16=0,AJ16<>0),1,"") | AY16: Absent | AZ16: A | BB16: Attendance Ratio | BC16: =IFERROR(AS20/SUM($AS$20:$AS$24),"-") -> -
AJ17: =COUNTIF(E17:AI17,$AJ$13) -> 0 | AK17: =COUNTIF(E17:AI17,$AK$13) -> 0 | AL17: =COUNTIF(E17:AI17,$AL$13) -> 0 | AM17: =COUNTIF(E17:AI17,$AM$13) -> 0 | AN17: =COUNTIF(E17:AI17,$AN$13) -> 0 | AO17: =IF(AND(D17<>"",AK17=0,AL17=0,AM17=0,AN17=0,AJ17<>0),1,"") | AY17: Holiday | AZ17: H
AJ18: =COUNTIF(E18:AI18,$AJ$13) -> 0 | AK18: =COUNTIF(E18:AI18,$AK$13) -> 0 | AL18: =COUNTIF(E18:AI18,$AL$13) -> 0 | AM18: =COUNTIF(E18:AI18,$AM$13) -> 0 | AN18: =COUNTIF(E18:AI18,$AN$13) -> 0 | AO18: =IF(AND(D18<>"",AK18=0,AL18=0,AM18=0,AN18=0,AJ18<>0),1,"") | AY18: Sick Leave | AZ18: SL
AJ19: =COUNTIF(E19:AI19,$AJ$13) -> 0 | AK19: =COUNTIF(E19:AI19,$AK$13) -> 0 | AL19: =COUNTIF(E19:AI19,$AL$13) -> 0 | AM19: =COUNTIF(E19:AI19,$AM$13) -> 0 | AN19: =COUNTIF(E19:AI19,$AN$13) -> 0 | AO19: =IF(AND(D19<>"",AK19=0,AL19=0,AM19=0,AN19=0,AJ19<>0),1,"") | AY19: Casual | AZ19: CL | BB19: Present Total | BC19: =SUM(AJ14:AJ1001) -> 2
AJ20: =COUNTIF(E20:AI20,$AJ$13) -> 0 | AK20: =COUNTIF(E20:AI20,$AK$13) -> 0 | AL20: =COUNTIF(E20:AI20,$AL$13) -> 0 | AM20: =COUNTIF(E20:AI20,$AM$13) -> 0 | AN20: =COUNTIF(E20:AI20,$AN$13) -> 0 | AO20: =IF(AND(D20<>"",AK20=0,AL20=0,AM20=0,AN20=0,AJ20<>0),1,"") | AR20: =AY15&" :" -> Present : | AS20: =_xlfn.XLOOKUP($AS$14,$D$14:$D$10001,$AJ$14:$AJ$10001,"-") -> 0 | BB20: Difference | BC20: =SUM(AK14:AN1001) -> 2
AJ21: =COUNTIF(E21:AI21,$AJ$13) -> 0 | AK21: =COUNTIF(E21:AI21,$AK$13) -> 0 | AL21: =COUNTIF(E21:AI21,$AL$13) -> 0 | AM21: =COUNTIF(E21:AI21,$AM$13) -> 0 | AN21: =COUNTIF(E21:AI21,$AN$13) -> 0 | AO21: =IF(AND(D21<>"",AK21=0,AL21=0,AM21=0,AN21=0,AJ21<>0),1,"") | AR21: =AY16&" :" -> Absent : | AS21: =_xlfn.XLOOKUP($AS$14,$D$14:$D$10001,$AK$14:$AK$10001,"-") -> 0 | BB21: Ratio | BC21: =IFERROR(BC19/SUM(BC19:BC20),"-") -> 0.5
AJ22: =COUNTIF(E22:AI22,$AJ$13) -> 0 | AK22: =COUNTIF(E22:AI22,$AK$13) -> 0 | AL22: =COUNTIF(E22:AI22,$AL$13) -> 0 | AM22: =COUNTIF(E22:AI22,$AM$13) -> 0 | AN22: =COUNTIF(E22:AI22,$AN$13) -> 0 | AO22: =IF(AND(D22<>"",AK22=0,AL22=0,AM22=0,AN22=0,AJ22<>0),1,"") | AR22: =AY17&" :" -> Holiday : | AS22: =_xlfn.XLOOKUP($AS$14,$D$14:$D$10001,$AL$14:$AL$10001,"-") -> 0 | BB22: Full attendance | BC22: =COUNTIF(AO14:AO10001,1)&" People" -> 0 People
AJ23: =COUNTIF(E23:AI23,$AJ$13) -> 0 | AK23: =COUNTIF(E23:AI23,$AK$13) -> 0 | AL23: =COUNTIF(E23:AI23,$AL$13) -> 0 | AM23: =COUNTIF(E23:AI23,$AM$13) -> 0 | AN23: =COUNTIF(E23:AI23,$AN$13) -> 0 | AO23: =IF(AND(D23<>"",AK23=0,AL23=0,AM23=0,AN23=0,AJ23<>0),1,"") | AR23: =AY18&" :" -> Sick Leave : | AS23: =_xlfn.XLOOKUP($AS$14,$D$14:$D$10001,$AM$14:$AM$10001,"-") -> 0 | BB23: Number of employees | BC23: =COUNTA(D14:D10001)&" People" -> 2 People
AJ24: =COUNTIF(E24:AI24,$AJ$13) -> 0 | AK24: =COUNTIF(E24:AI24,$AK$13) -> 0 | AL24: =COUNTIF(E24:AI24,$AL$13) -> 0 | AM24: =COUNTIF(E24:AI24,$AM$13) -> 0 | AN24: =COUNTIF(E24:AI24,$AN$13) -> 0 | AO24: =IF(AND(D24<>"",AK24=0,AL24=0,AM24=0,AN24=0,AJ24<>0),1,"") | AR24: =AY19&" :" -> Casual : | AS24: =_xlfn.XLOOKUP($AS$14,$D$14:$D$10001,$AN$14:$AN$10001,"-") -> 0
AJ25: =COUNTIF(E25:AI25,$AJ$13) -> 0 | AK25: =COUNTIF(E25:AI25,$AK$13) -> 0 | AL25: =COUNTIF(E25:AI25,$AL$13) -> 0 | AM25: =COUNTIF(E25:AI25,$AM$13) -> 0 | AN25: =COUNTIF(E25:AI25,$AN$13) -> 0 | AO25: =IF(AND(D25<>"",AK25=0,AL25=0,AM25=0,AN25=0,AJ25<>0),1,"")
AJ26: =COUNTIF(E26:AI26,$AJ$13) -> 0 | AK26: =COUNTIF(E26:AI26,$AK$13) -> 0 | AL26: =COUNTIF(E26:AI26,$AL$13) -> 0 | AM26: =COUNTIF(E26:AI26,$AM$13) -> 0 | AN26: =COUNTIF(E26:AI26,$AN$13) -> 0 | AO26: =IF(AND(D26<>"",AK26=0,AL26=0,AM26=0,AN26=0,AJ26<>0),1,"")
AJ27: =COUNTIF(E27:AI27,$AJ$13) -> 0 | AK27: =COUNTIF(E27:AI27,$AK$13) -> 0 | AL27: =COUNTIF(E27:AI27,$AL$13) -> 0 | AM27: =COUNTIF(E27:AI27,$AM$13) -> 0 | AN27: =COUNTIF(E27:AI27,$AN$13) -> 0 | AO27: =IF(AND(D27<>"",AK27=0,AL27=0,AM27=0,AN27=0,AJ27<>0),1,"")
AJ28: =COUNTIF(E28:AI28,$AJ$13) -> 0 | AK28: =COUNTIF(E28:AI28,$AK$13) -> 0 | AL28: =COUNTIF(E28:AI28,$AL$13) -> 0 | AM28: =COUNTIF(E28:AI28,$AM$13) -> 0 | AN28: =COUNTIF(E28:AI28,$AN$13) -> 0 | AO28: =IF(AND(D28<>"",AK28=0,AL28=0,AM28=0,AN28=0,AJ28<>0),1,"")
AJ29: =COUNTIF(E29:AI29,$AJ$13) -> 0 | AK29: =COUNTIF(E29:AI29,$AK$13) -> 0 | AL29: =COUNTIF(E29:AI29,$AL$13) -> 0 | AM29: =COUNTIF(E29:AI29,$AM$13) -> 0 | AN29: =COUNTIF(E29:AI29,$AN$13) -> 0 | AO29: =IF(AND(D29<>"",AK29=0,AL29=0,AM29=0,AN29=0,AJ29<>0),1,"")
AJ30: =COUNTIF(E30:AI30,$AJ$13) -> 0 | AK30: =COUNTIF(E30:AI30,$AK$13) -> 0 | AL30: =COUNTIF(E30:AI30,$AL$13) -> 0 | AM30: =COUNTIF(E30:AI30,$AM$13) -> 0 | AN30: =COUNTIF(E30:AI30,$AN$13) -> 0 | AO30: =IF(AND(D30<>"",AK30=0,AL30=0,AM30=0,AN30=0,AJ30<>0),1,"")
AJ31: =COUNTIF(E31:AI31,$AJ$13) -> 0 | AK31: =COUNTIF(E31:AI31,$AK$13) -> 0 | AL31: =COUNTIF(E31:AI31,$AL$13) -> 0 | AM31: =COUNTIF(E31:AI31,$AM$13) -> 0 | AN31: =COUNTIF(E31:AI31,$AN$13) -> 0 | AO31: =IF(AND(D31<>"",AK31=0,AL31=0,AM31=0,AN31=0,AJ31<>0),1,"")
AJ32: =COUNTIF(E32:AI32,$AJ$13) -> 0 | AK32: =COUNTIF(E32:AI32,$AK$13) -> 0 | AL32: =COUNTIF(E32:AI32,$AL$13) -> 0 | AM32: =COUNTIF(E32:AI32,$AM$13) -> 0 | AN32: =COUNTIF(E32:AI32,$AN$13) -> 0 | AO32: =IF(AND(D32<>"",AK32=0,AL32=0,AM32=0,AN32=0,AJ32<>0),1,"")
AJ33: =COUNTIF(E33:AI33,$AJ$13) -> 0 | AK33: =COUNTIF(E33:AI33,$AK$13) -> 0 | AL33: =COUNTIF(E33:AI33,$AL$13) -> 0 | AM33: =COUNTIF(E33:AI33,$AM$13) -> 0 | AN33: =COUNTIF(E33:AI33,$AN$13) -> 0 | AO33: =IF(AND(D33<>"",AK33=0,AL33=0,AM33=0,AN33=0,AJ33<>0),1,"")
AJ34: =COUNTIF(E34:AI34,$AJ$13) -> 0 | AK34: =COUNTIF(E34:AI34,$AK$13) -> 0 | AL34: =COUNTIF(E34:AI34,$AL$13) -> 0 | AM34: =COUNTIF(E34:AI34,$AM$13) -> 0 | AN34: =COUNTIF(E34:AI34,$AN$13) -> 0 | AO34: =IF(AND(D34<>"",AK34=0,AL34=0,AM34=0,AN34=0,AJ34<>0),1,"")
AJ35: =COUNTIF(E35:AI35,$AJ$13) -> 0 | AK35: =COUNTIF(E35:AI35,$AK$13) -> 0 | AL35: =COUNTIF(E35:AI35,$AL$13) -> 0 | AM35: =COUNTIF(E35:AI35,$AM$13) -> 0 | AN35: =COUNTIF(E35:AI35,$AN$13) -> 0 | AO35: =IF(AND(D35<>"",AK35=0,AL35=0,AM35=0,AN35=0,AJ35<>0),1,"")
AJ36: =COUNTIF(E36:AI36,$AJ$13) -> 0 | AK36: =COUNTIF(E36:AI36,$AK$13) -> 0 | AL36: =COUNTIF(E36:AI36,$AL$13) -> 0 | AM36: =COUNTIF(E36:AI36,$AM$13) -> 0 | AN36: =COUNTIF(E36:AI36,$AN$13) -> 0 | AO36: =IF(AND(D36<>"",AK36=0,AL36=0,AM36=0,AN36=0,AJ36<>0),1,"")
... AJ1001: =COUNTIF(E1001:AI1001,$AJ$13) -> 0 | AK1001: =COUNTIF(E1001:AI1001,$AK$13) -> 0 | AL1001: =COUNTIF(E1001:AI1001,$AL$13) -> 0 | AM1001: =COUNTIF(E1001:AI1001,$AM$13) -> 0 | AN1001: =COUNTIF(E1001:AI1001,$AN$13) -> 0 | AO1001: =IF(AND(D1001<>"",AK1001=0,AL1001=0,AM1001=0,AN1001=0,AJ1001<>0),1,"")

Sheet 6
C2: Employee Attendance Tracker
AR6: Statistical Year： | AS6: ='2'!AS6 -> 2026
AR8: Statistical Month： | AS8: 6
C10: Attendance Record
E11: =IF(E12="","",COUNTIF(E14:E10001,$AJ$13)) -> 0 | F11: =IF(F12="","",COUNTIF(F14:F10001,$AJ$13)) -> 0 | G11: =IF(G12="","",COUNTIF(G14:G10001,$AJ$13)) -> 0 | H11: =IF(H12="","",COUNTIF(H14:H10001,$AJ$13)) -> 0 | I11: =IF(I12="","",COUNTIF(I14:I10001,$AJ$13)) -> 0 | J11: =IF(J12="","",COUNTIF(J14:J10001,$AJ$13)) -> 0 | K11: =IF(K12="","",COUNTIF(K14:K10001,$AJ$13)) -> 0 | L11: =IF(L12="","",COUNTIF(L14:L10001,$AJ$13)) -> 0 | ... AI11: =IF(AI12="","",COUNTIF(AI14:AI10001,$AJ$13))
C12: No. | D12: Name | E12: =DATE($AS$6,$AS$8,1) -> 46174 | F12: =IFERROR(IF(MONTH(E12+1)<>$AS$8,"",E12+1),"") -> 46175 | G12: =IFERROR(IF(MONTH(F12+1)<>$AS$8,"",F12+1),"") -> 46176 | H12: =IFERROR(IF(MONTH(G12+1)<>$AS$8,"",G12+1),"") -> 46177 | I12: =IFERROR(IF(MONTH(H12+1)<>$AS$8,"",H12+1),"") -> 46178 | J12: =IFERROR(IF(MONTH(I12+1)<>$AS$8,"",I12+1),"") -> 46179 | K12: =IFERROR(IF(MONTH(J12+1)<>$AS$8,"",J12+1),"") -> 46180 | L12: =IFERROR(IF(MONTH(K12+1)<>$AS$8,"",K12+1),"") -> 46181 | M12: =IFERROR(IF(MONTH(L12+1)<>$AS$8,"",L12+1),"") -> 46182 | ... AI12: =IFERROR(IF(MONTH(AH12+1)<>$AS$8,"",AH12+1),"") | AJ12: Totals | AR12: Employee Query | AY12: Menu Custom
AJ13: ='6'!AZ15 -> P | AK13: ='6'!AZ16 -> A | AL13: ='6'!AZ17 -> H | AM13: ='6'!AZ18 -> SL | AN13: ='6'!AZ19 -> CL
AJ14: =COUNTIF(E14:AI14,$AJ$13) -> 0 | AK14: =COUNTIF(E14:AI14,$AK$13) -> 0 | AL14: =COUNTIF(E14:AI14,$AL$13) -> 0 | AM14: =COUNTIF(E14:AI14,$AM$13) -> 0 | AN14: =COUNTIF(E14:AI14,$AN$13) -> 0 | AO14: =IF(AND(D14<>"",AK14=0,AL14=0,AM14=0,AN14=0,AJ14<>0),1,"") | AR14: Employee： | AY14: Mean | AZ14: Display | BB14: Query： | BC14: =AS14 -> 0
AJ15: =COUNTIF(E15:AI15,$AJ$13) -> 0 | AK15: =COUNTIF(E15:AI15,$AK$13) -> 0 | AL15: =COUNTIF(E15:AI15,$AL$13) -> 0 | AM15: =COUNTIF(E15:AI15,$AM$13) -> 0 | AN15: =COUNTIF(E15:AI15,$AN$13) -> 0 | AO15: =IF(AND(D15<>"",AK15=0,AL15=0,AM15=0,AN15=0,AJ15<>0),1,"") | AY15: Present | AZ15: P | BB15: No. | BC15: =_xlfn.XLOOKUP($AS$14,$D$14:$D$10001,$C$14:$C$10001,"-") -> 0
AJ16: =COUNTIF(E16:AI16,$AJ$13) -> 0 | AK16: =COUNTIF(E16:AI16,$AK$13) -> 0 | AL16: =COUNTIF(E16:AI16,$AL$13) -> 0 | AM16: =COUNTIF(E16:AI16,$AM$13) -> 0 | AN16: =COUNTIF(E16:AI16,$AN$13) -> 0 | AO16: =IF(AND(D16<>"",AK16=0,AL16=0,AM16=0,AN16=0,AJ16<>0),1,"") | AY16: Absent | AZ16: A | BB16: Attendance Ratio | BC16: =IFERROR(AS20/SUM($AS$20:$AS$24),"-") -> -
AJ17: =COUNTIF(E17:AI17,$AJ$13) -> 0 | AK17: =COUNTIF(E17:AI17,$AK$13) -> 0 | AL17: =COUNTIF(E17:AI17,$AL$13) -> 0 | AM17: =COUNTIF(E17:AI17,$AM$13) -> 0 | AN17: =COUNTIF(E17:AI17,$AN$13) -> 0 | AO17: =IF(AND(D17<>"",AK17=0,AL17=0,AM17=0,AN17=0,AJ17<>0),1,"") | AY17: Holiday | AZ17: H
AJ18: =COUNTIF(E18:AI18,$AJ$13) -> 0 | AK18: =COUNTIF(E18:AI18,$AK$13) -> 0 | AL18: =COUNTIF(E18:AI18,$AL$13) -> 0 | AM18: =COUNTIF(E18:AI18,$AM$13) -> 0 | AN18: =COUNTIF(E18:AI18,$AN$13) -> 0 | AO18: =IF(AND(D18<>"",AK18=0,AL18=0,AM18=0,AN18=0,AJ18<>0),1,"") | AY18: Sick Leave | AZ18: SL
